Workbook

Sheet cotação
A1: CAIXA ORTOPEDIA INFANTIL E RECONSTRUÇÃO
A2: ITEM | B2: QT | C2: DESCRITIVO FINAL | D2: DESCRITIVO PROPOSTA E CATALOGO | E2: CÓDIGO | F2: ANVISA | G2: UNITÁRIO | H2: TOTAL | I2: MARCA
A3: 1 | B3: 2 | C3: AFASTADOR LANGENBECK PEQUENO, 30x11 MM, 21 CM | D3: Afastador Langenbeck, 22cm 30x11mm | E3: 09-281-01 | F3: 81897710023 | G3: 256.95783 | H3: 513.91565 | I3: FENTEX
A4: 2 | B4: 2 | C4: AFASTADOR LANGENBECK PEQUENO, 50x11 MM, 21 CM | D4: Afastador Langenbeck, 22cm 50x11mm | E4: 09-281-05 | F4: 81897710023 | G4: 269.07848 | H4: 538.15696 | I4: FENTEX
A5: 3 | B5: 1 | C5: AFASTADOR FARABEUF, 12 CM | D5: Afastador Farabeuf Conjunto Completo, 12cm | E5: 09-573-00 | F5: 81897710023 | G5: 315.54098 | H5: 315.54098 | I5: FENTEX
A6: 4 | B6: 1 | C6: AFASTADOR FARABEUF, 17 x 20 CM | D6: Afastador Farabeuf Conjunto Completo, 17x20cm | E6: 09-576-00 | F6: 81897710021 | G6: 315.54098 | H6: 315.54098 | I6: FENTEX
A7: 5 | B7: 4 | C7: PINÇA ALLIS DELICADA, ATRAUMÁTICA 16 CM | D7: Pinça Allis, Atraumatica, Delicada, 16cm | E7: 18-110-16 | F7: 81897710001 | G7: 770.87348 | H7: 3083.4939 | I7: FENTEX
A8: 6 | B8: 4 | C8: PINÇA ALLIS 5X6 DENTES, 15 CM | D8: Pinça Allis, 5x6 dentes, 15cm | E8: 18-104-15 | F8: 81897710001 | G8: 239.18087 | H8: 956.72348 | I8: FENTEX
A9: 7 | B9: 4 | C9: PORTA AGULHA FORTE, COM VIDEA, 18 CM | D9: Porta Agulha forte 18cm com videa | E9: 13-190-12 | F9: 81897710001 | G9: 868.64674 | H9: 3474.587 | I9: FENTEX
A10: 8 | B10: 1 | C10: SACABOCADO RUSKIN, DELICADO, RETO, 3MM X 15 CM | D10: Sacabocado Ruskin-Mini Bone Rongeur, delicado, Reta, 15cm, 3mm | E10: 13-898-15 | F10: 81897710001 | G10: 1368.0176 | H10: 1368.0176 | I10: FENTEX
A11: 9 | B11: 1 | C11: SACABOCADO STILLE RUSKIN, CURVO, 23 CM | D11: Sacabocado Ruskin Bone Rongeur, curva, 23cm | E11: 13-891-23 | F11: 81897710001 | G11: 1878.7011 | H11: 1878.7011 | I11: FENTEX
A12: 10 | B12: 2 | C12: SPREADER PEQUENO, 16 CM | D12: Afastador Spreader Pequeno, 16.5cm | E12: 15-605-16 | F12: 81897710001 | G12: 1250 | H12: 2500 | I12: FENTEX
A13: 11 | B13: 2 | C13: SPREADER GRANDE, 26 CM | D13: Afastador Spreader Grande, 27cm | E13: 15-605-27 | F13: 81897710001 | G13: 1250 | H13: 2500 | I13: FENTEX
A14: 12 | B14: 1 | C14: FORMÃO LAMBOTTE RETO, 6 MM X 17 CM | D14: Formao Lambotte Osteótomo 17cm, 6mm - reto | E14: 13-342-06 | F14: 81897710018 | G14: 228.6763 | H14: 228.6763 | I14: FENTEX
... A23: 21 | B23: 1 | C23: OSTEÓTOMO, COM CABO, CURVO, 19 MM X 20 CM | D23: Smith-Petersen Osteótomo, Curvo, 20cm, 19mm | E23: 13-321-19 | F23: 81897710018 | G23: 689.66511 | H23: 689.66511 | I23: FENTEX
A24: 22 | B24: 1 | C24: AFASTADOR QUADRADO PARA QUADRIL (NORTE SUL) | D24: Afastador Norte Sul para quadril | E24: 11602 | F24: 81087610008 | G24: 8855 | H24: 8855 | I24: PRIME
A25: 23 | B25: 2 | C25: PORTA AGULHA DELICADO CRILE WOOD, COM VIDEA, 15 CM | D25: Porta-agulhas Crilewood,delicado, com videa, 15cm | E25: 11-604-15 | F25: 81897710001 | G25: 851.2738 | H25: 1702.5476 | I25: FENTEX
A26: 24 | B26: 2 | C26: PORTA AGULHA FORTE, COM VIDEA, 18 CM | D26: Porta agulha forte, 18cm, com videa | E26: 13-190-12 | F26: 81897710001 | G26: 868.64674 | H26: 1737.2935 | I26: FENTEX
A27: 25 | B27: 2 | C27: TESOURA DE GESSO | D27: Tesoura para gesso Lister, 18cm | E27: 05-830-18 | F27: 81897710017 | G27: 176.15348 | H27: 352.30696 | I27: FENTEX
A28: 26 | B28: 1 | C28: PINÇA ECHILIN, 3 MM X 23 CM | D28: Pinça Echlin Bone Rongeur, 23cm, 3mm | E28: 13-900-03 | F28: 81897710001 | G28: 2177.2732 | H28: 2177.2732 | I28: FENTEX
A29: 27 | B29: 1 | C29: PINÇA WOLF PARA RETIRADA GESSO, 18 CM | D29: Pinça de gesso Wolff 18cm | E29: 12-220-18 | F29: 81897710001 | G29: 1363.1693 | H29: 1363.1693 | I29: FENTEX
A30: 28 | B30: 1 | C30: PINÇA WOLF PARA RETIRADA GESSO, 24 CM | D30: Pinça de gesso Wolff, 24cm | E30: 12-220-24 | F30: 81897710001 | G30: 1859.308 | H30: 1859.308 | I30: FENTEX
A31: 29 | B31: 1 | C31: DESCOLADOR MOLT, 18 CM | D31: Descolador Dingman (Molt), 6.5mm,18cm | E31: HB5618-18 | F31: 81897710012 | G31: 562.47009 | H31: 562.47009 | I31: FENTEX
A32: 30 | B32: 1 | C32: DESCOLADOR COBB, 13 MM X 28 CM | D32: Descolador Cobb, 28cm 13mm | E32: 13-670-02 | F32: 81897710018 | G32: 591.0838 | H32: 591.0838 | I32: FENTEX
A33: 31 | B33: 1 | C33: DESCOLADOR COBB, 19 MM X 28 CM | D33: Descoaldor Cobb, 28cm 19mm | E33: 13-670-03 | F33: 81897710018 | G33: 591.0838 | H33: 591.0838 | I33: FENTEX
A34: 32 | B34: 1 | C34: CURETA VOLKMANN, TAMANHO 000, 17 CM | D34: Cureta Óssea Volkmann 17cm, n 000 | E34: 13-502-30 | F34: 81897710018 | G34: 230.69641 | H34: 230.69641 | I34: FENTEX
A35: 33 | B35: 1 | C35: CURETA VOLKMANN, TAMANHO 00, 17 CM | D35: Cureta Óssea Volkmann 17cm, n 00 | E35: 13-502-20 | F35: 81897710018 | G35: 230.69641 | H35: 230.69641 | I35: FENTEX
A36: 34 | B36: 1 | C36: CURETA VOLKMANN, TAMANHO 0, 17 CM | D36: Cureta Óssea Volkmann 17cm, n 0 | E36: 13-502-10 | F36: 81897710018 | G36: 230.69641 | H36: 230.69641 | I36: FENTEX
... A58: 56 | B58: 4 | C58: AFASTADOR SENN-MULLER, AGUDO, 16 CM | D58: Afastador Senn-Miller 16cm 7x8.5mm, agudo | E58: 09-186-16 | F58: 81897710023 | G58: 236.35272 | H58: 945.41087 | I58: FENTEX
A59: 57 | B59: 2 | C59: DISTRATOR HINTERMANN PEQUENO | D59: Distrator Osseo Pequeno Hintermann, para pinos 1.6 a 2.4mm, 15cm | E59: FX.62.312 | F59: 81897719006 | G59: 1692.4022 | H59: 3384.8043 | I59: FENTEX | J59: 4210-SB
A60: 58 | B60: 2 | C60: DISTRATOR HINTERMANN MÉDIO | D60: Distrator Osseo Grande Hintermann, para pinos 1.6 a 2.4mm, 20cm | E60: FX.62.313 | F60: 81897719006 | G60: 1812.262 | H60: 3624.5239 | I60: FENTEX | J60: 4101-LB
A61: 59 | B61: 1 | C61: RUGINA FARABEUF, CURVA, 15 CM | D61: Farabeuf Rugina, curva, 15cm | E61: 13-599-15 | F61: 81897710018 | G61: 260.19 | H61: 260.19 | I61: FENTEX
A62: 60 | B62: 1 | C62: RUGINA FARABEUF, RETA, 15 CM | D62: Farabeuf Rugina, reta, 15cm | E62: 13-598-15 | F62: 81897710018 | G62: 260.19 | H62: 260.19 | I62: FENTEX
A63: 61 | B63: 1 | C63: RUGINA LAMBOTTE, 20 MM X 21 CM | D63: Rugina Lambotte 21cm, 20mm | E63: 13-627-20 | F63: 81897710018 | G63: 376.14424 | H63: 376.14424 | I63: FENTEX
A64: 62 | B64: 1 | C64: RUGINA, RETA, 19 MM X 20 CM | D64: Rugina raspatória reta, 20cm, 19mm | E64: 13-602-20 | F64: 81897710018 | G64: 946.62293 | H64: 946.62293 | I64: FENTEX
A65: 63 | B65: 2 | C65: CONJUNTO DE CONTAINER, TAMPA COM FILTRO PERMANENTE E CESTO, TAMANHO INTERNO APROXIMADO 430X260X115 MM | D65: Contêiner 3/4 Modelo Padrão Não Perfurado com tampa com filtro labirinto e cesto, 475X272X116mm | E65: FX.21.399 | F65: Isento | G65: 17613.63 | H65: =B65*G65 -> 35227.26 | I65: FENTEX
E66: Total | H66: =SUM(H3:H65) -> 112820.76
A67: CAIXA COLUNA
A68: ITEM | B68: QT | C68: DESCRITIVO FINAL | D68: DESCRITIVO PROPOSTA E CATALOGO | E68: CÓDIGO | F68: ANVISA | G68: UNITÁRIO | H68: TOTAL | I68: MARCA
A69: 1 | B69: 2 | C69: AFASTADOR (AUTOESTÁTICO) BECKMAN ADSON, ARTICULADO, ROMBO, 30 CM | D69: Afastador autostatico articulado Beckmann-Adson 31cm 25,0x40mm 4,0x4,0 Dentes rombos | E69: 09-721-03 | F69: 81897710001 | G69: 2422.1103 | H69: 4844.2207 | I69: FENTEX
...

Sheet proposta RESUMIDA
A2: ITEM | B2: ESPECIFICAÇÃO | C2: CATMAT | D2: SIAFISICO | E2: UNIDADE DE MEDIDA | F2: QUANTIDADE TOTAL | G2: VALOR UNITÁRIO | H2: VALOR TOTAL | I2: unt | J2: total | K2: fator
A3: 1 | B3: Caixa cirurgia Ortopedia Infantil e Reconstrução, conforme descritivo do item 3 do termo de referência. Procedencia: Estados Unidos Marca/Fabricante:FENTEX/FENTEX SURGICAL e PRIME (nacional) Código e RMS: Diversos, conforme descrito na proposta e no catálogo. | C3: 395938 | D3: 5153298 | E3: UN | F3: 1 | G3: 125800 | H3: =G3*F3 -> 125800 | I3: 125792.84 | J3: =I3*F3 -> 125792.84 | K3: 3.84 | L3: 132288
A4: 2 | B4: Caixa cirurgia Coluna, conforme descritivo do item 3 do termo de referência. Procedencia: Estados Unidos. Marca/Fabricante: FENTEX/FENTEX SURGICAL. Código e RMS: Diversos, conforme descrito na proposta e no catálogo. | C4: 395938 | D4: 5745659 | E4: UN | F4: 1 | G4: 116940 | H4: =G4*F4 -> 116940 | I4: 116942.26 | J4: =I4*F4 -> 116942.26 | K4: 3.76 | L4: 118798
A5: 3 | B5: Caixa cirurgia Pé e Tornozelo, conforme descritivo do item 3 do termo de referência. Procedencia: Estados Unidos. Marca/Fabricante: FENTEX/FENTEX SURGICAL. Código e RMS: Diversos, conforme descritona proposta e no catálogo. | C5: 395938 | D5: 5745640 | E5: UN | F5: 3 | G5: 160960 | H5: =G5*F5 -> 482880 | I5: 160917.91 | J5: =I5*F5 -> 482753.73 | K5: 4.02 | L5: 165581
A6: 5 | B6: Caixa cirurgia Ombro, conforme descritivo do item 3 do termo de referência. Procedencia: Estados Unidos. Marca/Fabricante: FENTEX/FENTEX SURGICAL. Código e RMS: Diversos, conforme descrito na proposta e no catálogo. | C6: 395939 | D6: 5826560 | E6: UN | F6: 2 | G6: 62270 | H6: =G6*F6 -> 124540 | I6: 62176.69 | J6: =I6*F6 -> 124353.38 | K6: 4.24 | L6: 69151
A7: 6 | B7: Caixa cirurgia Prótese Total de Quadril, conforme descritivo do item 3 do termo de referência. Procedencia: Estados Unidos. Marca/Fabricante: FENTEX/FENTEX SURGICAL. Código e RMS: Diversos, conforme descrito na proposta e no catálogo. | C7: 395938 | D7: 5825601 | E7: UN | F7: 4 | G7: 75080 | H7: =G7*F7 -> 300320 | I7: 74983.03 | J7: =I7*F7 -> 299932.12 | K7: 4.76 | L7: 85572
G8: TOTAL | H8: =SUM(H3:H7) -> 1150480 | J8: =SUM(J3:J7) -> 1149774.3

Sheet Planilha5
A2: ITEM | B2: ESPECIFICAÇÃO | C2: CATMAT | D2: SIAFISICO | E2: UNIDADE DE MEDIDA | F2: QUANTIDADE TOTAL | G2: VALOR UNITÁRIO | H2: VALOR TOTAL | I2: unt | J2: total | K2: fator
A3: 2 | B3: Caixa cirurgia Coluna, conforme descritivo do item 3 do termo de referência. Procedencia: Estados Unidos. Marca/Fabricante: FENTEX/FENTEX SURGICAL. Código e RMS: Diversos, conforme descrito na proposta e no catálogo. | C3: 395938 | D3: 5745659 | E3: UN | F3: 1 | G3: 116940 | H3: =G3*F3 -> 116940 | I3: 116942.26 | J3: =I3*F3 -> 116942.26 | K3: 3.76 | L3: 118798
A4: 3 | B4: Caixa cirurgia Pé e Tornozelo, conforme descritivo do item 3 do termo de referência. Procedencia: Estados Unidos. Marca/Fabricante: FENTEX/FENTEX SURGICAL. Código e RMS: Diversos, conforme descritona proposta e no catálogo. | C4: 395938 | D4: 5745640 | E4: UN | F4: 3 | G4: 160960 | H4: =G4*F4 -> 482880 | I4: 160917.91 | J4: =I4*F4 -> 482753.73 | K4: 4.02 | L4: 165581
A5: 5 | B5: Caixa cirurgia Ombro, conforme descritivo do item 3 do termo de referência. Procedencia: Estados Unidos. Marca/Fabricante: FENTEX/FENTEX SURGICAL. Código e RMS: Diversos, conforme descrito na proposta e no catálogo. | C5: 395939 | D5: 5826560 | E5: UN | F5: 2 | G5: 62270 | H5: =G5*F5 -> 124540 | I5: 62176.69 | J5: =I5*F5 -> 124353.38 | K5: 4.24 | L5: 69151
A6: 6 | B6: Caixa cirurgia Prótese Total de Quadril, conforme descritivo do item 3 do termo de referência. Procedencia: Estados Unidos. Marca/Fabricante: FENTEX/FENTEX SURGICAL. Código e RMS: Diversos, conforme descrito na proposta e no catálogo. | C6: 395938 | D6: 5825601 | E6: UN | F6: 4 | G6: 75080 | H6: =G6*F6 -> 300320 | I6: 74983.03 | J6: =I6*F6 -> 299932.12 | K6: 4.76 | L6: 85572
G7: TOTAL | H7: =SUM(H3:H6) -> 1024680 | J7: =SUM(J3:J6) -> 1023981.5
H10: 1024680

Sheet PROPOSTA ITEM A ITEM
C1: ITEM 1: CAIXA ORTOPEDIA INFANTIL E RECONSTRUÇÃO
A2: ITEM | B2: QT | C2: DESCRITIVO | D2: CÓDIGO | E2: ANVISA | F2: MARCA
A3: 1 | B3: 2 | C3: Afastador Langenbeck, 22cm 30x11mm | D3: 09-281-01 | E3: 81897710023 | F3: FENTEX
A4: 2 | B4: 2 | C4: Afastador Langenbeck, 22cm 50x11mm | D4: 09-281-05 | E4: 81897710023 | F4: FENTEX
A5: 3 | B5: 1 | C5: Afastador Farabeuf Conjunto Completo, 12cm | D5: 09-573-00 | E5: 81897710023 | F5: FENTEX
A6: 4 | B6: 1 | C6: Afastador Farabeuf Conjunto Completo, 17x20cm | D6: 09-576-00 | E6: 81897710021 | F6: FENTEX
A7: 5 | B7: 4 | C7: Pinça Allis, Atraumatica, Delicada, 16cm | D7: 18-110-16 | E7: 81897710001 | F7: FENTEX
A8: 6 | B8: 4 | C8: Pinça Allis, 5x6 dentes, 15cm | D8: 18-104-15 | E8: 81897710001 | F8: FENTEX
A9: 7 | B9: 4 | C9: Porta Agulha forte 18cm com videa | D9: 13-190-12 | E9: 81897710001 | F9: FENTEX
A10: 8 | B10: 1 | C10: Sacabocado Ruskin-Mini Bone Rongeur, delicado, Reta, 15cm, 3mm | D10: 13-898-15 | E10: 81897710001 | F10: FENTEX
A11: 9 | B11: 1 | C11: Sacabocado Ruskin Bone Rongeur, curva, 23cm | D11: 13-891-23 | E11: 81897710001 | F11: FENTEX
A12: 10 | B12: 2 | C12: Afastador Spreader Pequeno, 16.5cm | D12: 15-605-16 | E12: 81897710001 | F12: FENTEX
A13: 11 | B13: 2 | C13: Afastador Spreader Grande, 27cm | D13: 15-605-27 | E13: 81897710001 | F13: FENTEX
A14: 12 | B14: 1 | C14: Formao Lambotte Osteótomo 17cm, 6mm - reto | D14: 13-342-06 | E14: 81897710018 | F14: FENTEX
... A23: 21 | B23: 1 | C23: Smith-Petersen Osteótomo, Curvo, 20cm, 19mm | D23: 13-321-19 | E23: 81897710018 | F23: FENTEX
A24: 22 | B24: 1 | C24: Afastador Norte Sul para quadril | D24: 11602 | E24: 81087610008 | F24: PRIME
A25: 23 | B25: 2 | C25: Porta-agulhas Crilewood,delicado, com videa, 15cm | D25: 11-604-15 | E25: 81897710001 | F25: FENTEX
A26: 24 | B26: 2 | C26: Porta agulha forte, 18cm, com videa | D26: 13-190-12 | E26: 81897710001 | F26: FENTEX
A27: 25 | B27: 2 | C27: Tesoura para gesso Lister, 18cm | D27: 05-830-18 | E27: 81897710017 | F27: FENTEX
A28: 26 | B28: 1 | C28: Pinça Echlin Bone Rongeur, 23cm, 3mm | D28: 13-900-03 | E28: 81897710001 | F28: FENTEX
A29: 27 | B29: 1 | C29: Pinça de gesso Wolff 18cm | D29: 12-220-18 | E29: 81897710001 | F29: FENTEX
A30: 28 | B30: 1 | C30: Pinça de gesso Wolff, 24cm | D30: 12-220-24 | E30: 81897710001 | F30: FENTEX
A31: 29 | B31: 1 | C31: Descolador Dingman (Molt), 6.5mm,18cm | D31: HB5618-18 | E31: 81897710012 | F31: FENTEX
A32: 30 | B32: 1 | C32: Descolador Cobb, 28cm 13mm | D32: 13-670-02 | E32: 81897710018 | F32: FENTEX
A33: 31 | B33: 1 | C33: Descoaldor Cobb, 28cm 19mm | D33: 13-670-03 | E33: 81897710018 | F33: FENTEX
A34: 32 | B34: 1 | C34: Cureta Óssea Volkmann 17cm, n 000 | D34: 13-502-30 | E34: 81897710018 | F34: FENTEX
A35: 33 | B35: 1 | C35: Cureta Óssea Volkmann 17cm, n 00 | D35: 13-502-20 | E35: 81897710018 | F35: FENTEX
A36: 34 | B36: 1 | C36: Cureta Óssea Volkmann 17cm, n 0 | D36: 13-502-10 | E36: 81897710018 | F36: FENTEX
... A64: 62 | B64: 1 | C64: Rugina raspatória reta, 20cm, 19mm | D64: 13-602-20 | E64: 81897710018 | F64: FENTEX
A65: 63 | B65: 2 | C65: Contêiner 3/4 Modelo Padrão Não Perfurado com tampa com filtro labirinto e cesto, 475X272X116mm | D65: FX.21.399 | E65: Isento | F65: FENTEX
C66: CAIXA COLUNA
A67: ITEM | B67: QT | C67: DESCRITIVO | D67: CÓDIGO | E67: ANVISA | F67: MARCA
A68: 1 | B68: 2 | C68: Afastador autostatico articulado Beckmann-Adson 31cm 25,0x40mm 4,0x4,0 Dentes rombos | D68: 09-721-03 | E68: 81897710001 | F68: FENTEX
A69: 2 | B69: 2 | C69: Afastador Volkmann 1 pino romba 22cm | D69: 09-221-01 | E69: 81897710023 | F69: FENTEX
A70: 3 | B70: 2 | C70: Afastador Volkmann 2 pinos romba 22cm | D70: 09-221-02 | E70: 81897710023 | F70: FENTEX
A71: 4 | B71: 2 | C71: Afastador Volkmann 3 pinos romba 22cm | D71: 09-221-03 | E71: 81897710023 | F71: FENTEX
A72: 5 | B72: 2 | C72: Afastador Volkmann 4 pinos romba 22cm | D72: 09-221-04 | E72: 81897710023 | F72: FENTEX
A73: 6 | B73: 2 | C73: Afastador autostatico Weitlaner 20cm 3,0x4,0 dentes rombos | D73: 09-647-20 | E73: 81897710001 | F73: FENTEX
A74: 7 | B74: 1 | C74: Afastador Farabeuf Conjunto Completo, 17x20cm | D74: 09-576-00 | E74: 81897710021 | F74: FENTEX
A75: 8 | B75: 1 | C75: Afastador Farabeuf Conjunto Completo, 15cm | D75: 09-575-00 | E75: 81897710023 | F75: FENTEX
...

Sheet Planilha2
D8: PROPOSTA COMERCIAL
B12: Cliente | C12: IAMSPE | E12: Data:
B13: A/C | E13: Numero | F13: CTCXXX.25
B15: Cont | C15: QTD | D15: Caixa de Instrumental | E15: Valor por Caixa | F15: Valor Total
B16: 1 | C16: 1 | D16: CAIXA ORTOPEDIA INFANTIL E RECONSTRUÇÃO | E16: =cotação!H66 -> 112820.76 | F16: =C16*E16 -> 112820.76
B17: 2 | C17: 1 | D17: CAIXA COLUNA | E17: =cotação!H126 -> 109431.32 | F17: =C17*E17 -> 109431.32
B18: 3 | C18: 3 | D18: CAIXA PÉ E TORNOZELO | E18: =cotação!H211 -> 140964.97 | F18: =C18*E18 -> 422894.91
B19: 4 | C19: 2 | D19: CAIXA PRÓTESE TOTAL JOELHO | E19: =cotação!H253 -> 43947.363 | F19: =C19*E19 -> 87894.726
B20: 5 | C20: 2 | D20: CAIXA DE OMBRO | E20: =cotação!H289 -> 51271.352 | F20: =C20*E20 -> 102542.7
B21: 6 | C21: 4 | D21: CAIXA PRÓTESE TOTAL DE QUADRIL | E21: =cotação!H334 -> 55080.86 | F21: =C21*E21 -> 220323.44
D22: TOTAL | F22: =SUM(F16:F21) -> 1055907.9
B25: CONDIÇÕES COMERCIAIS:
B27: Marca | D27: Fentex
B28: Procedencia | D28: Estados Unidos (Frete e IPI inclusos)
B29: Prazo de Entrega | D29: 120 dias
B30: Prazo de Pagamento | D30: 28 dias
B31: Validade da Proposta | D31: 60 dias
B33: Garantia de 10 anos contra defeito de fabricação
B35: OBSERVAÇÕES:
B38: COMPOSIÇÕES DAS CAIXAS:

Sheet Planilha4
A2: ITEM | B2: ESPECIFICAÇÃO | C2: CATMAT | D2: SIAFISICO | E2: UNIDADE DE MEDIDA | F2: QUANTIDADE TOTAL
A3: 1 | B3: Caixa cirurgia Ortopedia Infantil e Reconstrução | C3: 395938 | D3: 5153298 | E3: UN | F3: 1
A4: 2 | B4: Caixa cirurgia Coluna | C4: 395938 | D4: 5745659 | E4: UN | F4: 1
A5: 3 | B5: Caixa cirurgia Pé e Tornozelo | C5: 395938 | D5: 5745640 | E5: UN | F5: 3
A6: 4 | B6: Caixa cirurgia Joelho | C6: 395938 | D6: 5151724 | E6: UN | F6: 2
A7: 5 | B7: Caixa cirurgia Ombro | C7: 395939 | D7: 5826560 | E7: UN | F7: 2
A8: 6 | B8: Caixa cirurgia Prótese Total de Quadril | C8: 395938 | D8: 5825601 | E8: UN | F8: 4

Sheet Planilha1
A1: CÓDIGO | B1: ANVISA
A2: 11602 | B2: 81087610008
A3: 18-110-16 | B3: 81897710001
A4: 18-104-15 | B4: 81897710001
A5: 13-190-12 | B5: 81897710001
A6: 13-898-15 | B6: 81897710001
A7: 13-891-23 | B7: 81897710001
A8: 15-605-16 | B8: 81897710001
A9: 15-605-27 | B9: 81897710001
A10: 11-604-15 | B10: 81897710001
A11: 13-190-12 | B11: 81897710001
A12: 13-900-03 | B12: 81897710001
A13: 12-220-18 | B13: 81897710001
A14: 12-220-24 | B14: 81897710001
... A272: FX.62.313 | B272: 81897719006
A273: CÓDIGO | B273: ANVISA
A274: CÓDIGO | B274: ANVISA
A275: CÓDIGO | B275: ANVISA
A276: CÓDIGO | B276: ANVISA
A277: FX.21.399 | B277: Isento
A278: FX.21.399 | B278: Isento
A279: FX.21.399 | B279: Isento
A280: FX.21.399 | B280: Isento
A281: FX.21.400 | B281: Isento
