Workbook

Sheet TR Final (2)
A2: Caixa de Instrumentais Cirúrgicos Cirurgia Geral
A3: ITEM | B3: DESCRITIVO | C3: QTD | D3: CODIGO | E3: REGISTRO ANVISA | F3: MARCA | G3: UNITARIO | H3: TOTAL
A4: 1 | B4: Afastador Farabeuf, par com 2 válvulas duplas de lâmina plana, 12cm | C4: 1
A5: 2 | B5: Afastador Farabeuf, par com 2 válvulas duplas de lâmina plana, 15cm | C5: 1
A6: 3 | B6: Alfinete de Segurança Mayo, 14cm | C6: 4
A7: 4 | B7: Conjunto com pleto de Aspiração Yankauer, contendo: 04 canulas intercambiáveis, oliva e cabo com apoio digital, 27cm | C7: 1
A8: 5 | B8: Cabo de bisturi nº 3, graduado em centímetros, 12cm | C8: 1
A9: 6 | B9: Cabo de bisturi nº 4, Standard, 12cm | C9: 1
A10: 7 | B10: Afastador Balfour, garras laterais aramadas com 100mm x 35mm, hastes curvas, abertura de 200mm, Acompanha válvula central plana com 100mm x 60mm | C10: 1
A11: 8 | B11: Pinça Allis, pontas retas c/ 5 x 6 dentes, 15cm | C11: 3
A12: 9 | B12: Pinça Allis, pontas retas c/ 5 x 6 dentes, 19cm | C12: 3
A13: 10 | B13: Pinça Anatômica Standard, pontas retas, largas com 1 x 2 dentes, 20cm | C13: 2
A14: 11 | B14: Pinça Babcok, pontas retas c/ conchas pequenas,fenestradas e wídia TC, 20cm | C14: 1
A15: 12 | B15: Pinça Toalha Backhaus, 13cm | C15: 10
... A44: 41 | B44: Conjunto de Container Sólido, tamanho 3/4, dimensões internas aproximadas 430x260x115 mm, inclui tampa, cesto e duas unidades de plaqueta de identificação | C44: 1
C45: =SUM(C4:C44) -> 94 | F45: TOTAL
A47: Caixa de Instrumentais Cirúrgicos Cirurgia Pediátrica
A48: ITEM | B48: DESCRITIVO | C48: QTD | D48: CODIGO | E48: REGISTRO ANVISA | F48: MARCA | G48: UNITARIO | H48: TOTAL
A49: 1 | B49: Alfinete de Segurança Mayo, 14cm | C49: 4
A50: 2 | B50: Bacia Redonda, 100 x 50mm | C50: 1
A51: 3 | B51: Afastador Mini-Langebeck, lâmina de 10mm x 6mm, 16cm | C51: 1
A52: 4 | B52: Pinça Cheron, pontas retas e serrilhadas, formato baioneta, 25cm | C52: 1
A53: 5 | B53: Pinça Foerster, pontas retas, com anéis fenestrados e serrilhados, 25cm | C53: 1
A54: 6 | B54: Pinça Foerster, pontas curvas, com anéis fenestrados e serrilhados, 25cm | C54: 1
A55: 7 | B55: Pinça Anatômica Standard, pontas retas, largas com 1 x 2 dentes, 16cm | C55: 1
A56: 8 | B56: Pinça Anatômica Standard, pontas retas, largas e serrilhadas, 16cm | C56: 1
A57: 9 | B57: Pinça Anatômica Standard, pontas retas, largas com 1 x 2 dentes, 14.5cm | C57: 2
A58: 10 | B58: Afastador Farabeuf, par com 2 válvulas duplas de lâmina plana, 15cm | C58: 1
A59: 11 | B59: Afastador Farabeuf, par com 2 válvulas duplas de lâmina plana, 12cm | C59: 1
A60: 12 | B60: Pinça Anatômica Adson, pontas retas, finas com 1 x 2 dentes, 15cm | C60: 1
... A81: 33 | B81: Conjunto de Container Sólido, tamanho 1/2, dimensões internas aproximadas 260x260x115 mm, inclui tampa, cesto e duas unidades de plaqueta de identificação | C81: 1
C82: =SUM(C49:C81) -> 57 | F82: TOTAL
A84: Caixa de Instrumentais Cirúrgicos Cirurgia Urológica
A85: ITEM | B85: DESCRITIVO | C85: QTD | D85: CODIGO | E85: REGISTRO ANVISA | F85: MARCA | G85: UNITARIO | H85: TOTAL
A86: 1 | B86: Afastador Farabeuf 10mm x 12cm infantil | C86: 1
A87: 2 | B87: Afastador Farabeuf 13mm x 15cm adulto | C87: 1
A88: 3 | B88: Afastador Gosset 24CM | C88: 1
A89: 4 | B89: Afastador Gosset 30CM | C89: 1
A90: 5 | B90: Afastador Langembeck 50x11mm 21cm | C90: 1
A91: 6 | B91: Afastador Langenbeck 40x11mm 21cm | C91: 1
...

Sheet GERAL
A1: ITEM | B1: NOME | C1: QTD | D1: VALOR UNIT | E1: VALOR TOTAL
A2: 1 | B2: Caixa de Instrumentais Cirúrgicos Cirurgia Geral | C2: 8 | D2: ='LISTAS PRECOS PARA PROPOSTA'!I44 -> 30924.92 | E2: =D2*C2 -> 247399.36
A3: 2 | B3: Caixa de Instrumentais Cirúrgicos Cirurgia Pediátrica | C3: 4 | D3: ='LISTAS PRECOS PARA PROPOSTA'!I81 -> 18590.8 | E3: =D3*C3 -> 74363.2
A4: 3 | B4: Caixa de Instrumentais Cirúrgicos Cirurgia Urológica | C4: 4 | D4: ='LISTAS PRECOS PARA PROPOSTA'!I148 -> 43317.152 | E4: =D4*C4 -> 173268.61
A5: 4 | B5: Caixa de Instrumentais Cirúrgicos Curetagem | C5: 2 | D5: ='LISTAS PRECOS PARA PROPOSTA'!I174 -> 14944.88 | E5: =D5*C5 -> 29889.76
A6: 5 | B6: Caixa de Instrumentais Cirúrgicos Histerectomia | C6: 4 | D6: ='LISTAS PRECOS PARA PROPOSTA'!I215 -> 33082.6 | E6: =D6*C6 -> 132330.4
A7: 6 | B7: Caixa de Instrumentais Cirúrgicos Laparotomia Ginecológica | C7: 4 | D7: ='LISTAS PRECOS PARA PROPOSTA'!I270 -> 39320.84 | E7: =D7*C7 -> 157283.36
A8: 7 | B8: Caixa de Instrumentais Cirúrgicos Laqueadura | C8: 4 | D8: ='LISTAS PRECOS PARA PROPOSTA'!I287 -> 12333.68 | E8: =D8*C8 -> 49334.72
A9: 8 | B9: Caixa de Instrumentais Cirúrgicos ORL | C9: 2 | D9: ='LISTAS PRECOS PARA PROPOSTA'!I332 -> 49770.368 | E9: =D9*C9 -> 99540.736
A10: 9 | B10: Caixa de Cesárea | C10: 16 | D10: ='LISTAS PRECOS PARA PROPOSTA'!I358 -> 16622.64 | E10: =D10*C10 -> 265962.24
A11: 10 | B11: Caixa de Parto Normal | C11: 4 | D11: ='LISTAS PRECOS PARA PROPOSTA'!I372 -> 10397.36 | E11: =D11*C11 -> 41589.44
A12: 11 | B12: Caixa de Instrumentais Cirúrgicos - Vascular Periférico | C12: 6 | D12: ='LISTAS PRECOS PARA PROPOSTA'!I446 -> 59102.36 | E12: =D12*C12 -> 354614.16
A13: 12 | B13: Caixa de Instrumentais Cirúrgicos – Dermato | C13: 3 | D13: ='LISTAS PRECOS PARA PROPOSTA'!I474 -> 13320.8 | E13: =D13*C13 -> 39962.4
A14: 13 | B14: Caixa de Instrumental Cirúrgico – Oftalmologia | C14: 12 | D14: ='LISTAS PRECOS PARA PROPOSTA'!I497 -> 26682.327 | E14: =D14*C14 -> 320187.92
A15: 14 | B15: Caixa de Cirurgia Vascular para Varizes | C15: 4 | D15: ='LISTAS PRECOS PARA PROPOSTA'!I528 -> 22615.4 | E15: =D15*C15 -> 90461.6
A16: 15 | B16: Caixa de Microcirurgia Vascular | C16: 4 | D16: ='LISTAS PRECOS PARA PROPOSTA'!I556 -> 11957.04 | E16: =D16*C16 -> 47828.16
A17: 16 | B17: Caixa de Revisão Uterina | C17: 6 | D17: ='LISTAS PRECOS PARA PROPOSTA'!I574 -> 12234.44 | E17: =D17*C17 -> 73406.64
A18: 17 | B18: Caixa de Sutura | C18: 20 | D18: ='LISTAS PRECOS PARA PROPOSTA'!I585 -> 1364.88 | E18: =D18*C18 -> 27297.6
A19: 18 | B19: Caixa Instrumental para Procedimentos Proctologia | C19: 4 | D19: ='LISTAS PRECOS PARA PROPOSTA'!I617 -> 18865.456 | E19: =D19*C19 -> 75461.824
A20: 19 | B20: Caixa Microcirúrgica Otológica | C20: 3 | D20: ='LISTAS PRECOS PARA PROPOSTA'!I648 -> 21892.184 | E20: =D20*C20 -> 65676.552
A21: 28 | B21: Caixa Instrumental Ortopédico | C21: 12 | D21: ='LISTAS PRECOS PARA PROPOSTA'!I708 -> 25370.336 | E21: =D21*C21 -> 304444.03
A22: 29 | B22: Caixa Mão/Punho | C22: 10 | D22: ='LISTAS PRECOS PARA PROPOSTA'!I752 -> 27586.264 | E22: =D22*C22 -> 275862.64
A23: 30 | B23: Caixa para Hemorroidectomia | C23: 10 | D23: ='LISTAS PRECOS PARA PROPOSTA'!I784 -> 18575.24 | E23: =D23*C23 -> 185752.4
A24: 31 | B24: Caixa Caixa Pé/Tornozelo | C24: 4 | D24: ='LISTAS PRECOS PARA PROPOSTA'!I837 -> 36741.304 | E24: =D24*C24 -> 146965.22
A25: 32 | B25: Caixa de Velas de Hegar | C25: 2
A26: 33 | B26: Avulsos | C26: 1
E27: =SUM(E2:E25) -> 3278883

Sheet TR
B1: Caixa de Instrumentais Cirúrgicos Cirurgia Geral
B2: ITEM | C2: DESCRITIVO | D2: QTD | E2: CODIGO | F2: REGISTRO ANVISA | G2: MARCA | H2: UNITARIO | I2: TOTAL
B3: 1 | C3: Afastador Farabeuf, par com 2 válvulas duplas de lâmina plana, 12cm | D3: 1
B4: 2 | C4: Afastador Farabeuf, par com 2 válvulas duplas de lâmina plana, 15cm | D4: 1
B5: 3 | C5: Alfinete de Segurança Mayo, 14cm | D5: 4
B6: 4 | C6: Conjunto com pleto de Aspiração Yankauer, contendo: 04 canulas intercambiáveis, oliva e cabo com apoio digital, 27cm | D6: 1
B7: 5 | C7: Cabo de bisturi nº 3, graduado em centímetros, 12cm | D7: 1
B8: 6 | C8: Cabo de bisturi nº 4, Standard, 12cm | D8: 1
B9: 7 | C9: Afastador Balfour, garras laterais aramadas com 100mm x 35mm, hastes curvas, abertura de 200mm, Acompanha válvula central plana com 100mm x 60mm | D9: 1
B10: 8 | C10: Pinça Allis, pontas retas c/ 5 x 6 dentes, 15cm | D10: 3
B11: 9 | C11: Pinça Allis, pontas retas c/ 5 x 6 dentes, 19cm | D11: 3
B12: 10 | C12: Pinça Anatômica Standard, pontas retas, largas com 1 x 2 dentes, 20cm | D12: 2
B13: 11 | C13: Pinça Babcok, pontas retas c/ conchas pequenas,fenestradas e wídia TC, 20cm | D13: 1
B14: 12 | C14: Pinça Toalha Backhaus, 13cm | D14: 10
... B43: 41 | C43: Conjunto de Container Sólido, tamanho 3/4, dimensões internas aproximadas 430x260x115 mm, inclui tampa, cesto e duas unidades de plaqueta de identificação | D43: 1
D44: =SUM(D3:D43) -> 94
B46: Caixa de Instrumentais Cirúrgicos Cirurgia Pediátrica
B47: ITEM | C47: DESCRITIVO | D47: QTD | E47: CODIGO | F47: REGISTRO ANVISA | G47: MARCA | H47: UNITARIO | I47: TOTAL
B48: 1 | C48: Bacia Redonda, 100 x 50mm | D48: 1
B49: 2 | C49: Afastador Mini-Langebeck, lâmina de 10mm x 6mm, 16cm | D49: 1
B50: 3 | C50: Pinça Cheron, pontas retas e serrilhadas, formato baioneta, 25cm | D50: 1
B51: 4 | C51: Pinça Foerster, pontas retas, com anéis fenestrados e serrilhados, 25cm | D51: 1
B52: 5 | C52: Pinça Foerster, pontas curvas, com anéis fenestrados e serrilhados, 25cm | D52: 1
B53: 6 | C53: Pinça Anatômica Standard, pontas retas, largas com 1 x 2 dentes, 16cm | D53: 1
B54: 7 | C54: Pinça Anatômica Standard, pontas retas, largas e serrilhadas, 16cm | D54: 1
B55: 8 | C55: Pinça Anatômica Standard, pontas retas, largas com 1 x 2 dentes, 14.5cm | D55: 2
B56: 9 | C56: Afastador Farabeuf, par com 2 válvulas duplas de lâmina plana, 15cm | D56: 1
B57: 10 | C57: Afastador Farabeuf, par com 2 válvulas duplas de lâmina plana, 12cm | D57: 1
B58: 11 | C58: Pinça Anatômica Adson, pontas retas, finas com 1 x 2 dentes, 15cm | D58: 1
B59: 12 | C59: Pinça Anatômica Adson, pontas retas, finas e serrilhadas, 15cm | D59: 1
... B79: 32 | C79: Conjunto de Container Sólido, tamanho 1/2, dimensões internas aproximadas 260x260x115 mm, inclui tampa, cesto e duas unidades de plaqueta de identificação | D79: 1
D80: =SUM(D48:D79) -> 53
B82: Caixa de Instrumentais Cirúrgicos Cirurgia Urológica
B83: ITEM | C83: DESCRITIVO | D83: QTD | E83: CODIGO | F83: REGISTRO ANVISA | G83: MARCA | H83: UNITARIO | I83: TOTAL
B84: 1 | C84: Afastador Farabeuf 10mm x 12cm infantil | D84: 1
B85: 2 | C85: Afastador Farabeuf 13mm x 15cm adulto | D85: 1
B86: 3 | C86: Afastador Gosset 24CM | D86: 1
B87: 4 | C87: Afastador Gosset 30CM | D87: 1
B88: 5 | C88: Afastador Langembeck 50x11mm 21cm | D88: 1
B89: 6 | C89: Afastador Langenbeck 40x11mm 21cm | D89: 1
...

Sheet LISTAS PRECOS PARA PROPOSTA
B1: Caixa de Instrumentais Cirúrgicos Cirurgia Geral
B2: ITEM | C2: DESCRITIVO | D2: QTD | E2: CODIGO | F2: REGISTRO ANVISA | G2: MARCA | H2: UNITARIO | I2: TOTAL
B3: 1 | C3: Afastador Farabeuf, par com 2 válvulas duplas de lâmina plana, 12cm | D3: 1 | H3: 281.16 | I3: 281.16
B4: 2 | C4: Afastador Farabeuf, par com 2 válvulas duplas de lâmina plana, 15cm | D4: 1 | H4: 281.16 | I4: 281.16
B5: 3 | C5: Alfinete de Segurança Mayo, 14cm | D5: 4 | H5: 83.52 | I5: 334.08
B6: 4 | C6: Conjunto com pleto de Aspiração Yankauer, contendo: 04 canulas intercambiáveis, oliva e cabo com apoio digital, 27cm | D6: 1 | H6: 498.6 | I6: 498.6
B7: 5 | C7: Cabo de bisturi nº 3, graduado em centímetros, 12cm | D7: 1 | H7: 74.88 | I7: 74.88
B8: 6 | C8: Cabo de bisturi nº 4, Standard, 12cm | D8: 1 | H8: 46.44 | I8: 46.44
B9: 7 | C9: Afastador Balfour, garras laterais aramadas com 100mm x 35mm, hastes curvas, abertura de 200mm, Acompanha válvula central plana com 100mm x 60mm | D9: 1 | H9: 1934.28 | I9: 1934.28
B10: 8 | C10: Pinça Allis, pontas retas c/ 5 x 6 dentes, 15cm | D10: 3 | H10: 213.12 | I10: 639.36
B11: 9 | C11: Pinça Allis, pontas retas c/ 5 x 6 dentes, 19cm | D11: 3 | H11: 288 | I11: 864
B12: 10 | C12: Pinça Anatômica Standard, pontas retas, largas com 1 x 2 dentes, 20cm | D12: 2 | H12: 136.08 | I12: 272.16
B13: 11 | C13: Pinça Babcok, pontas retas c/ conchas pequenas,fenestradas e wídia TC, 20cm | D13: 1 | H13: 1024.56 | I13: 1024.56
B14: 12 | C14: Pinça Toalha Backhaus, 13cm | D14: 10 | H14: 113.4 | I14: 1134
... B43: 41 | C43: Conjunto de Container Sólido, tamanho 3/4, dimensões internas aproximadas 430x260x115 mm, inclui tampa, cesto e duas unidades de plaqueta de identificação | D43: 1 | H43: 8480 | I43: 8480
D44: =SUM(D3:D43) -> 94 | I44: =SUM(I3:I43) -> 30924.92
B46: Caixa de Instrumentais Cirúrgicos Cirurgia Pediátrica
B47: ITEM | C47: DESCRITIVO | D47: QTD | E47: CODIGO | F47: REGISTRO ANVISA | G47: MARCA | H47: UNITARIO | I47: TOTAL
B48: 1 | C48: Alfinete de Segurança Mayo, 14cm | D48: 4 | H48: 83.52 | I48: 334.08
B49: 2 | C49: Bacia Redonda, 100 x 50mm | D49: 1 | H49: 146.88 | I49: 146.88
B50: 3 | C50: Afastador Mini-Langebeck, lâmina de 10mm x 6mm, 16cm | D50: 1 | H50: 198.72 | I50: 198.72
B51: 4 | C51: Pinça Cheron, pontas retas e serrilhadas, formato baioneta, 25cm | D51: 1 | H51: 566.64 | I51: 566.64
B52: 5 | C52: Pinça Foerster, pontas retas, com anéis fenestrados e serrilhados, 25cm | D52: 1 | H52: 268.2 | I52: 268.2
B53: 6 | C53: Pinça Foerster, pontas curvas, com anéis fenestrados e serrilhados, 25cm | D53: 1 | H53: 271.44 | I53: 271.44
B54: 7 | C54: Pinça Anatômica Standard, pontas retas, largas com 1 x 2 dentes, 16cm | D54: 1 | H54: 109.08 | I54: 109.08
B55: 8 | C55: Pinça Anatômica Standard, pontas retas, largas e serrilhadas, 16cm | D55: 1 | H55: 104.76 | I55: 104.76
B56: 9 | C56: Pinça Anatômica Standard, pontas retas, largas com 1 x 2 dentes, 14.5cm | D56: 2 | H56: 98.28 | I56: 196.56
B57: 10 | C57: Afastador Farabeuf, par com 2 válvulas duplas de lâmina plana, 15cm | D57: 1 | H57: 281.16 | I57: 281.16
B58: 11 | C58: Afastador Farabeuf, par com 2 válvulas duplas de lâmina plana, 12cm | D58: 1 | H58: 281.16 | I58: 281.16
B59: 12 | C59: Pinça Anatômica Adson, pontas retas, finas com 1 x 2 dentes, 15cm | D59: 1 | H59: 114.48 | I59: 114.48
... B80: 33 | C80: Conjunto de Container Sólido, tamanho 1/2, dimensões internas aproximadas 260x260x115 mm, inclui tampa, cesto e duas unidades de plaqueta de identificação | D80: 1 | H80: 9400 | I80: 9400
D81: =SUM(D48:D80) -> 57 | I81: =SUM(I48:I80) -> 18590.8
B83: Caixa de Instrumentais Cirúrgicos Cirurgia Urológica
B84: ITEM | C84: DESCRITIVO | D84: QTD | E84: CODIGO | F84: REGISTRO ANVISA | G84: MARCA | H84: UNITARIO | I84: TOTAL
B85: 1 | C85: Afastador Farabeuf 10mm x 12cm infantil | D85: 1 | H85: 105.696 | I85: =H85*D85 -> 105.696
B86: 2 | C86: Afastador Farabeuf 13mm x 15cm adulto | D86: 1 | H86: 105.696 | I86: =H86*D86 -> 105.696
B87: 3 | C87: Afastador Gosset 24CM | D87: 1 | H87: 1920.096 | I87: =H87*D87 -> 1920.096
B88: 4 | C88: Afastador Gosset 30CM | D88: 1 | H88: 1152 | I88: =H88*D88 -> 1152
B89: 5 | C89: Afastador Langembeck 50x11mm 21cm | D89: 1 | H89: 192.096 | I89: =H89*D89 -> 192.096
B90: 6 | C90: Afastador Langenbeck 40x11mm 21cm | D90: 1 | H90: 192.096 | I90: =H90*D90 -> 192.096
...
