Workbook

Sheet PROPOSTAS RESUMO
B1: Anexo III - PROPOSTA DE PREÇOS (MODELO DE DESCRITIVO)
B3: DADOS DO FORNECEDOR
B5: Fornecedor:
B6: CNPJ/CPF: | F6: Inscrição Estadual:
B7: Endereço:
B8: Bairro:
B9: CEP: | E9: Cidade: | F9: Estado:
B10: Telefone: | E10: e-mail:
B11: Banco: | E11: Agência: Conta corrente:
B14: Constitui objeto desta licitação: Contratação de Serviço de Locação de Caixas de Instrumental Cirúrgico, para atender o Hospital Universitário do Oeste do Paraná
M16: PESQUISA AGEIS
K17: Valor Edital
B18: 1 | C18: Serviço de Locação de Instrumentais para Cirurgia Cardíaca | H18: =SUM(H20:H22) -> 80778.664 | K18: 80784.49 | N18: 82068.99
B19: SUBITEM | C19: Caixa de Instrumental | D19: QTD | E19: Valor Unit Bruto | F19: Valor Total Bruto | G19: Valor Unit sem ICMS | H19: Valor Total sem ICMS | I19: Aliquota % ICMS
B20: 1.1 | C20: CAIXA CIRURGIA CORONÁRIA | D20: 3 | E20: ='PROPOSTAS LISTA '!I56 -> 10909.354 | F20: =E20*D20 -> 32728.061 | G20: ='PROPOSTAS LISTA '!K56 -> 10909.354 | H20: =G20*D20 -> 32728.061 | I20: 18 | L20: 3 | M20: 11187.74 | N20: 33563.21
B21: 1.2 | C21: CAIXA CIRURGIA DE VÁLVULA CARDÍACA | D21: 3 | E21: ='PROPOSTAS LISTA '!I116 -> 14131.736 | F21: =E21*D21 -> 42395.209 | G21: ='PROPOSTAS LISTA '!K116 -> 14131.736 | H21: =G21*D21 -> 42395.209 | I21: 18 | L21: 3 | M21: 14128.6 | N21: 42385.81
B22: 1.3 | C22: CAIXA CIRURGIA CARDIOVASCULAR DELICADA | D22: 3 | E22: ='PROPOSTAS LISTA '!I138 -> 2298.9408 | F22: =E22*D22 -> 6896.8224 | G22: ='PROPOSTAS LISTA '!K138 -> 1885.1315 | H22: =G22*D22 -> 5655.3944 | I22: 18 | L22: 3 | M22: 2039.99 | N22: 6119.97
B24: 2 | C24: Serviço de Locação de Instrumentais para Cirurgia de Laparotomia | H24: =SUM(H26:H27) -> 38641.751 | K24: 38653.83 | N24: 37619.34
B25: SUBITEM | C25: Caixa de Instrumental | D25: QTD | E25: Valor Unit Bruto | F25: Valor Total Bruto | G25: Valor Unit sem ICMS | H25: Valor Total sem ICMS | I25: Aliquota % ICMS
B26: 2.1 | C26: CAIXA LAPAROTOMIA ADULTO | D26: 4 | E26: ='PROPOSTAS LISTA '!I195 -> 5405.6146 | F26: =E26*D26 -> 21622.458 | G26: ='PROPOSTAS LISTA '!K195 -> 5405.6146 | H26: =G26*D26 -> 21622.458 | I26: 18 | L26: 4 | M26: 5484.52 | N26: 21938.09
B27: 2.2 | C27: CAIXA LAPAROTOMIA INFANTIL | D27: 4 | E27: ='PROPOSTAS LISTA '!I249 -> 4254.8231 | F27: =E27*D27 -> 17019.292 | G27: ='PROPOSTAS LISTA '!K249 -> 4254.8231 | H27: =G27*D27 -> 17019.292 | I27: 18 | L27: 4 | M27: 3920.31 | N27: 15681.26
B29: 3 | C29: Serviço de Locação de Instrumentais para Cirurgia Geral | H29: =SUM(H31:H32) -> 11799.075 | K29: 11842.24 | N29: 11686.72
B30: SUBITEM | C30: Caixa de Instrumental | D30: QTD | E30: Valor Unit Bruto | F30: Valor Total Bruto | G30: Valor Unit sem ICMS | H30: Valor Total sem ICMS | I30: Aliquota % ICMS | L30: 3 | M30: 2478.99 | N30: 7436.97
B31: 3.1 | C31: CAIXA CIRURGIA GERAL MEDIO PORTE | D31: 3 | E31: ='PROPOSTAS LISTA '!I290 -> 2503.7376 | F31: =E31*D31 -> 7511.2128 | G31: ='PROPOSTAS LISTA '!K290 -> 2503.7376 | H31: =G31*D31 -> 7511.2128 | I31: 18 | L31: 2 | M31: 2124.88 | N31: 4249.75
B32: 3.2 | C32: CAIXA CIRURGIA GERAL PEQUENO PORTE | D32: 2 | E32: ='PROPOSTAS LISTA '!I324 -> 2143.9309 | F32: =E32*D32 -> 4287.8618 | G32: ='PROPOSTAS LISTA '!K324 -> 2143.9309 | H32: =G32*D32 -> 4287.8618 | I32: 18
B34: 4 | C34: Serviço de Locação de Instrumentais para Cirurgia de Otorrinolaringologia | H34: =SUM(H36:H37) -> 12016.738 | K34: 12066.44 | N34: 12066.44
B35: SUBITEM | C35: Caixa de Instrumental | D35: QTD | E35: Valor Unit Bruto | F35: Valor Total Bruto | G35: Valor Unit sem ICMS | H35: Valor Total sem ICMS | I35: Aliquota % ICMS
B36: 4.1 | C36: CAIXA RINOPLASTIA | D36: 1 | E36: ='PROPOSTAS LISTA '!I349 -> 7065.3468 | F36: =E36*D36 -> 7065.3468 | G36: ='PROPOSTAS LISTA '!K349 -> 7065.3468 | H36: =G36*D36 -> 7065.3468 | I36: 18 | L36: 1 | M36: 1734.89 | N36: 1734.89
B37: 4.2 | C37: CAIXA OTORRINO PARA PS | D37: 1 | E37: ='PROPOSTAS LISTA '!I377 -> 4951.3913 | F37: =E37*D37 -> 4951.3913 | G37: ='PROPOSTAS LISTA '!K377 -> 4951.3913 | H37: =G37*D37 -> 4951.3913 | I37: 18 | L37: 1 | M37: 3850.78 | N37: 3850.78
B39: 5 | C39: Serviço de Locação de Instrumetais para Cirurgia Neurológicas | H39: =SUM(H41:H43) -> 67769.798 | K39: 67698.94 | N39: 65418.83
B40: SUBITEM | C40: Caixa de Instrumental | D40: QTD | E40: Valor Unit Bruto | F40: Valor Total Bruto | G40: Valor Unit sem ICMS | H40: Valor Total sem ICMS | I40: Aliquota % ICMS | L40: 2 | M40: 12596.89 | N40: 25193.77
B41: 5.1 | C41: CAIXA DE LAMINECTOMIA | D41: 2 | E41: ='PROPOSTAS LISTA '!I448 -> 13580.871 | F41: =E41*D41 -> 27161.743 | G41: ='PROPOSTAS LISTA '!K448 -> 13580.871 | H41: =G41*D41 -> 27161.743 | I41: 18 | L41: 2 | M41: 14194.66 | N41: 28389.32
B42: 5.2 | C42: CAIXA CIRURGIA CRANIOTOMIA | D42: 2 | E42: ='PROPOSTAS LISTA '!I542 -> 17031.561 | F42: =E42*D42 -> 34063.122 | G42: ='PROPOSTAS LISTA '!K542 -> 17031.561 | H42: =G42*D42 -> 34063.122 | I42: 18 | L42: 2 | M42: 5917.87 | N42: 11835.74
B43: 5.3 | C43: CAIXA BASICA NEUROCIRURGIA | D43: 1 | E43: ='PROPOSTAS LISTA '!I599 -> 6544.9331 | F43: =E43*D43 -> 6544.9331 | G43: ='PROPOSTAS LISTA '!K599 -> 6544.9331 | H43: =G43*D43 -> 6544.9331 | I43: 18
B45: 6 | C45: Serviço de Locação de Instrumentais para Cirurgias Gastroenterológica | H45: =SUM(H47:H48) -> 19952.699 | K45: 19959.99 | N45: 19199.97
B46: SUBITEM | C46: Caixa de Instrumental | D46: QTD | E46: Valor Unit Bruto | F46: Valor Total Bruto | G46: Valor Unit sem ICMS | H46: Valor Total sem ICMS | I46: Aliquota % ICMS
B47: 6.1 | C47: CAIXA DE COLECISTECTOMIA | D47: 3 | E47: ='PROPOSTAS LISTA '!I652 -> 3465.7358 | F47: =E47*D47 -> 10397.207 | G47: ='PROPOSTAS LISTA '!K652 -> 3465.7358 | H47: =G47*D47 -> 10397.207 | I47: 18 | L47: 3 | M47: 4231.32 | N47: 12693.95
B48: 6.2 | C48: CAIXA APENDICECTOMIA E CISTOSTOMIA | D48: 3 | E48: ='PROPOSTAS LISTA '!I685 -> 3185.1638 | F48: =E48*D48 -> 9555.4913 | G48: ='PROPOSTAS LISTA '!K685 -> 3185.1638 | H48: =G48*D48 -> 9555.4913 | I48: 18 | L48: 3 | M48: 2168.68 | N48: 6506.03
B50: 7 | C50: Serviço de Locação de Instrumentais para Cirurgias Torácica | H50: =SUM(H52:H53) -> 13300.689 | K50: 13301.7 | N50: 12916.11
B51: SUBITEM | C51: Caixa de Instrumental | D51: QTD | E51: Valor Unit Bruto | F51: Valor Total Bruto | G51: Valor Unit sem ICMS | H51: Valor Total sem ICMS | I51: Aliquota % ICMS
...

Sheet PROPOSTAS LISTA 
D2: SUBITEM 1.1 - Caixa para Cirurgia Coronária
C3: ITEM | D3: DESCRITIVO | E3: QTD | F3: CODIGO | G3: ANVISA | H3: Valor Unit Bruto | I3: Valor Total Bruto | J3: Valor Unit sem ICMS | K3: Valor Total sem ICMS | L3: Aliquota % ICMS | N3: ICMS
A4: 2. 2-Acessório afastador mamária acoplado. | B4: AI00743 | C4: 1 | D4: Acessório afastador mamária acoplado | E4: 2 | F4: FX.41.684 | G4: 81897719006 | H4: 353.99104 | I4: =H4*E4 -> 707.98208 | J4: =O4 -> 353.99104 | K4: =J4*E4 -> 707.98208 | L4: 0 | N4: =H4*L4 -> 0 | O4: =H4-N4 -> 353.99104
A5: 3. 1-Afastador Dinkhuysen mamária, tamanho adulto; | B5: AI01471 | C5: 2 | D5: Afastador Dinkhuysen mamária, tamanho adulto | E5: 1 | F5: FX.41.685 | G5: 81897719006 | H5: 270.32 | I5: =H5*E5 -> 270.32 | J5: =O5 -> 270.32 | K5: =J5*E5 -> 270.32 | L5: 0 | N5: =H5*L5 -> 0 | O5: =H5-N5 -> 270.32
A6: 4. 2-Afastador Finochietto, tamanho adulto, deverá vir com acessório para afastador finochietto aclopado; | B6: FX.14.456 | C6: 3 | D6: Finochietto Afastador de Costelas, 74x64mm, 245mm - inclui acessórios | E6: 2 | F6: FX.14.456 | G6: 81897719002 | H6: 473.3248 | I6: =H6*E6 -> 946.6496 | J6: =O6 -> 473.3248 | K6: =J6*E6 -> 946.6496 | L6: 0 | N6: =H6*L6 -> 0 | O6: =H6-N6 -> 473.3248
A7: 5. 2-Afastador Autostático, com 4 ganchos no afastador, apresentando 15 cm | B7: FX.11.218 | C7: 4 | D7: Afastador Mollison, garras com 4 x 4 dentes, 15cm | E7: 2 | F7: FX.11.218 | G7: 81897719002 | H7: 121.71328 | I7: =H7*E7 -> 243.42656 | J7: =O7 -> 121.71328 | K7: =J7*E7 -> 243.42656 | L7: 0 | N7: =H7*L7 -> 0 | O7: =H7-N7 -> 121.71328
A8: 6. 2-Afastador Farabeuf, tamanho grande, com 15 cm de comprimento; | B8: FX.10.729 | C8: 5 | D8: Afastador Farabeuf, par com 2 válvulas duplas de lâmina plana, 15cm | E8: 2 | F8: FX.10.729 | G8: 81897719002 | H8: 16.91456 | I8: =H8*E8 -> 33.82912 | J8: =O8 -> 16.91456 | K8: =J8*E8 -> 33.82912 | L8: 0 | N8: =H8*L8 -> 0 | O8: =H8-N8 -> 16.91456
A9: 7. 2-Cabo de Bisturi, longo n° 3, com 20 cm de comprimento; | B9: FX.18.092 | C9: 6 | D9: Cabo de Bisturi, #3L, 20cm | E9: 2 | F9: FX.18.092 | G9: 81897719002 | H9: 12.17216 | I9: =H9*E9 -> 24.34432 | J9: =O9 -> 12.17216 | K9: =J9*E9 -> 24.34432 | L9: 0 | N9: =H9*L9 -> 0 | O9: =H9-N9 -> 12.17216
A10: 8. 2-Cabo de Bisturi, n° 4, com 13 cm de comprimento; | B10: FX.09.156 | C10: 7 | D10: Cabo de bisturi nº 4, standard, 12cm | E10: 2 | F10: FX.09.156 | G10: 81897719002 | H10: 6.77248 | I10: =H10*E10 -> 13.54496 | J10: =O10 -> 6.77248 | K10: =J10*E10 -> 13.54496 | L10: 0 | N10: =H10*L10 -> 0 | O10: =H10-N10 -> 6.77248
A11: 9. 2-Cabo de Bisturi, n° 7, com 16,5 cm de comprimento; | B11: FX.18.097 | C11: 8 | D11: Cabo de Bisturi, #7, 16cm | E11: 2 | F11: FX.18.097 | G11: 81897719002 | H11: 8.112 | I11: =H11*E11 -> 16.224 | J11: =O11 -> 8.112 | K11: =J11*E11 -> 16.224 | L11: 0 | N11: =H11*L11 -> 0 | O11: =H11-N11 -> 8.112
A12: 10. 2-Cortador de Fio de Aço, com 20 cm de comprimento; | B12: 13-190-20 | C12: 9 | D12: Cortador de fios de aço, lâminas anguladas com wídea TC e corte diagonal, 20cm | E12: 2 | F12: 13-190-20 | G12: 81897710001 | H12: 202.86656 | I12: =H12*E12 -> 405.73312 | J12: =O12 -> 202.86656 | K12: =J12*E12 -> 405.73312 | L12: 0 | N12: =H12*L12 -> 0 | O12: =H12-N12 -> 202.86656
A13: 11. 4-Clamp tipo Bulldog, ponta angulada, com 12 mm de comprimento; | B13: FX.13.961 | C13: 10 | D13: Gregory Bulldog Clamp, Atraumatica, maleavel, angulada, 11cm | E13: 4 | F13: FX.13.961 | G13: 81897719002 | H13: 74.36416 | I13: =H13*E13 -> 297.45664 | J13: =O13 -> 74.36416 | K13: =J13*E13 -> 297.45664 | L13: 0 | N13: =H13*L13 -> 0 | O13: =H13-N13 -> 74.36416
A14: 12. 2-Cureta tipo Simon, reta, com ponta rígida concha, com 8,5 mm de diâmetro 20CM | B14: CRIAR | C14: 11 | D14: Simon Colher Uterina, afiada, 8.5mm, 20cm | E14: 2 | F14: FX.41.653 | G14: 81897719006 | H14: 29.73568 | I14: =H14*E14 -> 59.47136 | J14: =O14 -> 29.73568 | K14: =J14*E14 -> 59.47136 | L14: 0 | N14: =H14*L14 -> 0 | O14: =H14-N14 -> 29.73568
A15: 13. 2-Estilete Rummel, com 26 cm de comprimento; | B15: FX.14.236 | C15: 12 | D15: Estilete para passar fios, ponta em gancho, calibre de 1.5mm, 26cm | E15: 2 | F15: FX.14.236 | G15: 81897719002 | H15: 18.94464 | I15: =H15*E15 -> 37.88928 | J15: =O15 -> 18.94464 | K15: =J15*E15 -> 37.88928 | L15: 0 | N15: =H15*L15 -> 0 | O15: =H15-N15 -> 18.94464
... A51: 49. 4-Tesoura de Mayo, reta, com 14 cm de comprimento; | B51: FX.09.375 | C51: 48 | D51: Tesoura Mayo, lâminas retas, largas com pontas rombas, 14.5cm | E51: 4 | F51: FX.09.375 | G51: 81897719002 | H51: 17.36384 | I51: =H51*E51 -> 69.45536 | J51: =O51 -> 17.36384 | K51: =J51*E51 -> 69.45536 | L51: 0 | N51: =H51*L51 -> 0 | O51: =H51-N51 -> 17.36384
A52: 50. 1- Caixa perfurada, com travas, para armazenamento de todo conjunto de | B52: FX.60.075 | C52: 49 | D52: Box de container tamanho 1/1, em alumínio anodizado, dimensões internas 550x260x135 mm | E52: 1 | F52: FX.60.075 | G52: Isento | H52: 590.62848 | I52: =H52*E52 -> 590.62848 | J52: =O52 -> 590.62848 | K52: =J52*E52 -> 590.62848 | L52: 0 | N52: =H52*L52 -> 0 | O52: =H52-N52 -> 590.62848
B53: FX.60.009 | C53: 50 | D53: Tampa para container tamanho 1/1, com sistema de barreira permanente, silicone em toda extensão para perfeita vedação, cor vermelha | E53: 1 | F53: FX.60.009 | G53: Isento | H53: 681.45792 | I53: =H53*E53 -> 681.45792 | J53: =O53 -> 681.45792 | K53: =J53*E53 -> 681.45792 | L53: 0 | N53: =H53*L53 -> 0 | O53: =H53-N53 -> 681.45792
B54: FX.60.666 | C54: 51 | D54: Cesto aramado compatível com box tamanho 1/1, com pés, dimensões 539x252x110 mm | E54: 1 | F54: FX.60.666 | G54: Isento | H54: 456.06912 | I54: =H54*E54 -> 456.06912 | J54: =O54 -> 456.06912 | K54: =J54*E54 -> 456.06912 | L54: 0 | N54: =H54*L54 -> 0 | O54: =H54-N54 -> 456.06912
B55: FX.62.227 | C55: 52 | D55: Placa de Identificação propria para a base de container, em aluminio na cor vermelha | E55: 2 | F55: FX.62.227 | G55: Isento | H55: 9.57632 | I55: =H55*E55 -> 19.15264 | J55: =O55 -> 9.57632 | K55: =J55*E55 -> 19.15264 | L55: 0 | N55: =H55*L55 -> 0 | O55: =H55-N55 -> 9.57632
D56: Total | E56: =SUM(E4:E55) -> 139 | I56: =SUM(I4:I55) -> 10909.354 | K56: =SUM(K4:K55) -> 10909.354 | N56: =H56*L56 -> 0 | O56: =H56-N56 -> 0
N57: =H57*L57 -> 0 | O57: =H57-N57 -> 0
D58: Subitem 1.2 - Caixa para Cirurgia de Válvula Cardíaca | N58: =H58*L58 -> 0 | O58: =H58-N58 -> 0
C59: ITEM | D59: DESCRITIVO | E59: QTD | F59: CODIGO | G59: ANVISA | H59: Valor Unit Bruto | I59: Valor Total Bruto | J59: Valor Unit sem ICMS | K59: Valor Total sem ICMS | L59: Aliquota % ICMS | N59: =H59*L59 -> #VALUE! | O59: =H59-N59 -> #VALUE!
A60: 2. 2-Afastador Autostático, com 4 ganchos no afastador, com 15 cm de comprimento; | B60: FX.11.218 | C60: 1 | D60: Afastador Mollison, garras com 4 x 4 dentes agudos, hastes comcurva acentuada, movimento por cremalheira, 15cm | E60: 2 | F60: FX.11.218 | G60: 81897719002 | H60: 121.71328 | I60: =H60*E60 -> 243.42656 | J60: =O60 -> 121.71328 | K60: =J60*E60 -> 243.42656 | L60: 0 | N60: =H60*L60 -> 0 | O60: =H60-N60 -> 121.71328
A61: 3. 2-Afastador Ventrículo, tamanho pequeno, com 20cm de comprimento; | B61: QZ.044.01 | C61: 2 | D61: Afastador Ventrículo, tamanho pequeno, 20cm | E61: 2 | F61: QZ.044.01 | G61: 10301950027 | H61: 209.85536 | I61: =H61*E61 -> 419.71072 | J61: =O61 -> 209.85536 | K61: =J61*E61 -> 419.71072 | L61: 0 | N61: =H61*L61 -> 0 | O61: =H61-N61 -> 209.85536
A62: 4. 2-Afastador Ventrículo, tamanho médio, com 20cm de comprimento; | B62: QZ.044.02 | C62: 3 | D62: Afastador Ventrículo, tamanho médio, 20cm | E62: 2 | F62: QZ.044.02 | G62: 10301950027 | H62: 209.85536 | I62: =H62*E62 -> 419.71072 | J62: =O62 -> 209.85536 | K62: =J62*E62 -> 419.71072 | L62: 0 | N62: =H62*L62 -> 0 | O62: =H62-N62 -> 209.85536
A63: 5. 1-Afastador Atril Esquerdo, com 21 cm de comprimento; | B63: FX.11.108 | C63: 4 | D63: Afastador Cooley, válvula aramada serrilhada, fenestrada, curva p/direita, com dimensões de 45mm x 48mm, 21.5cm | E63: 1 | F63: FX.11.108 | G63: 81897719002 | H63: 135.21664 | I63: =H63*E63 -> 135.21664 | J63: =O63 -> 135.21664 | K63: =J63*E63 -> 135.21664 | L63: 0 | N63: =H63*L63 -> 0 | O63: =H63-N63 -> 135.21664
A64: 6. 1-Afastador Atril Direito, com 21 cm de comprimento; | B64: FX.11.107 | C64: 5 | D64: Afastador Cooley, válvula aramada lisa, fenestrada, curva p/ direita, com dimensões de 45mm x 48mm, 21.5cm | E64: 1 | F64: FX.11.107 | G64: 81897719002 | H64: 135.21664 | I64: =H64*E64 -> 135.21664 | J64: =O64 -> 135.21664 | K64: =J64*E64 -> 135.21664 | L64: 0 | N64: =H64*L64 -> 0 | O64: =H64-N64 -> 135.21664
A65: 7. 2-Afastador de externo, simples, com 30 cm de comprimento; | B65: QZ.010.04 | C65: 6 | D65: Afastador de externo, simples, 30cm | E65: 2 | F65: QZ.010.04 | G65: 10301950026 | H65: 879.02464 | I65: =H65*E65 -> 1758.0493 | J65: =O65 -> 879.02464 | K65: =J65*E65 -> 1758.0493 | L65: 0 | N65: =H65*L65 -> 0 | O65: =H65-N65 -> 879.02464
A66: 8. 2-Afastador Farabeuf, tamanho grande, com 15cm de comprimento; | B66: FX.10.729 | C66: 7 | D66: Afastador Farabeuf, par com 2 válvulas duplas de lâmina plana, 15cm | E66: 2 | F66: FX.10.729 | G66: 81897719002 | H66: 16.91456 | I66: =H66*E66 -> 33.82912 | J66: =O66 -> 16.91456 | K66: =J66*E66 -> 33.82912 | L66: 0 | N66: =H66*L66 -> 0 | O66: =H66-N66 -> 16.91456
A67: 9. 2-Cabo de Bisturi, n. 3, longo, com 20cm de comprimento; | B67: FX.18.092 | C67: 8 | D67: Cabo de Bisturi, #3L, 20cm | E67: 2 | F67: FX.18.092 | G67: 81897719002 | H67: 12.17216 | I67: =H67*E67 -> 24.34432 | J67: =O67 -> 12.17216 | K67: =J67*E67 -> 24.34432 | L67: 0 | N67: =H67*L67 -> 0 | O67: =H67-N67 -> 12.17216
A68: 10. 2-Cabo de Bisturi, n.4, com 13cm de comprimeno; | B68: FX.09.156 | C68: 9 | D68: Cabo de bisturi nº 4, standard, 12cm | E68: 2 | F68: FX.09.156 | G68: 81897719002 | H68: 6.77248 | I68: =H68*E68 -> 13.54496 | J68: =O68 -> 6.77248 | K68: =J68*E68 -> 13.54496 | L68: 0 | N68: =H68*L68 -> 0 | O68: =H68-N68 -> 6.77248
A69: 11. 2-Cabo de Bisturi, n. 7, com 16,5cm de comprimento; | B69: FX.18.097 | C69: 10 | D69: Cabo de Bisturi, #7, 16cm | E69: 2 | F69: FX.18.097 | G69: 81897719002 | H69: 8.112 | I69: =H69*E69 -> 16.224 | J69: =O69 -> 8.112 | K69: =J69*E69 -> 16.224 | L69: 0 | N69: =H69*L69 -> 0 | O69: =H69-N69 -> 8.112
A70: 12. 1-Cânula para Cardioplegia, tipo Dinkhuysen ponta 90°, com 20cm de comprimento; | B70: AI02166 | C70: 11 | D70: Cânula para Cardioplegia, tipo Dinkhuysen ponta 90°, 20cm | E70: 1 | F70: FX.41.673 | G70: 81897710042 | H70: 281.73184 | I70: =H70*E70 -> 281.73184 | J70: =O70 -> 281.73184 | K70: =J70*E70 -> 281.73184 | L70: 0 | N70: =H70*L70 -> 0 | O70: =H70-N70 -> 281.73184
A71: 13. 1-Cânula para Cardioplegia, tipo Dinkhuysen ponta 30°, cin 20cm de comprimento; | B71: AI02167 | C71: 12 | D71: Cânula para Cardioplegia, tipo Dinkhuysen ponta 30°, 20cm | E71: 1 | F71: FX.41.674 | G71: 81897710042 | H71: 281.73184 | I71: =H71*E71 -> 281.73184 | J71: =O71 -> 281.73184 | K71: =J71*E71 -> 281.73184 | L71: 0 | N71: =H71*L71 -> 0 | O71: =H71-N71 -> 281.73184
... A105: 47. 4-Porta Agulha Mayo Hegar, com vídea, com 20cm de comprimento; | B105: FX.11.902 | C105: 46 | D105: Porta Agulha Mayo-Hegar, pontas com wídea TC, retas, 20cm | E105: 4 | F105: FX.11.902 | G105: 81897719003 | H105: 91.27872 | I105: =H105*E105 -> 365.11488 | J105: =O105 -> 91.27872 | K105: =J105*E105 -> 365.11488 | L105: 0 | N105: =H105*L105 -> 0 | O105: =H105-N105 -> 91.27872
A106: 48. 4-Porta Agulha Mayo Hegar com vídea, com 23cm de comprimento; | B106: FX.11.903 | C106: 47 | D106: Porta Agulha Mayo-Hegar, pontas com wídea TC, retas, 24cm | E106: 4 | F106: FX.11.903 | G106: 81897719003 | H106: 101.4208 | I106: =H106*E106 -> 405.6832 | J106: =O106 -> 101.4208 | K106: =J106*E106 -> 405.6832 | L106: 0 | N106: =H106*L106 -> 0 | O106: =H106-N106 -> 101.4208
A107: 49. 4-Tesoura de Mayo, reta, com 14cm de comprimento; | B107: FX.09.375 | C107: 48 | D107: Tesoura Mayo, lâminas retas, largas com pontas rombas, 14.5cm | E107: 4 | F107: FX.09.375 | G107: 81897719002 | H107: 17.36384 | I107: =H107*E107 -> 69.45536 | J107: =O107 -> 17.36384 | K107: =J107*E107 -> 69.45536 | L107: 0 | N107: =H107*L107 -> 0 | O107: =H107-N107 -> 17.36384
A108: 50. 2-Tesoura de Tubo, reta forte, com 20cm de comprimento; | B108: FX.10.608 | C108: 49 | D108: Pinça Presbyterian para tubos, pontas retas e lisas, 20cm | E108: 2 | F108: FX.10.608 | G108: 81897719002 | H108: 25.68384 | I108: =H108*E108 -> 51.36768 | J108: =O108 -> 25.68384 | K108: =J108*E108 -> 51.36768 | L108: 0 | N108: =H108*L108 -> 0 | O108: =H108-N108 -> 25.68384
A109: 51. 2-Tesoura Metzenbaum, curva, com 14cm de comprimento; | B109: FX.09.450 | C109: 50 | D109: Tesoura Metzenbaum, lâminas curvas, finas com pontas rombas, 14.5cm | E109: 2 | F109: FX.09.450 | G109: 81897719002 | H109: 16.06592 | I109: =H109*E109 -> 32.13184 | J109: =O109 -> 16.06592 | K109: =J109*E109 -> 32.13184 | L109: 0 | N109: =H109*L109 -> 0 | O109: =H109-N109 -> 16.06592
...
