Workbook

Sheet PROPOSTAS RESUMO
B1: Anexo III - PROPOSTA DE PREÇOS (MODELO DE DESCRITIVO)
B3: DADOS DO FORNECEDOR
B5: Fornecedor:
B6: CNPJ/CPF: | F6: Inscrição Estadual:
B7: Endereço:
B8: Bairro:
B9: CEP: | E9: Cidade: | F9: Estado:
B10: Telefone: | E10: e-mail:
B11: Banco: | E11: Agência: Conta corrente:
B14: Constitui objeto desta licitação: Contratação de Serviço de Locação de Caixas de Instrumental Cirúrgico, para atender o Hospital Universitário do Oeste do Paraná
N16: PESQUISA AGEIS
K17: Valor Edital
B18: 1 | C18: Serviço de Locação de Instrumentais para Cirurgia Cardíaca | H18: =SUM(H20:H22) -> 70378.139 | K18: 80784.49 | L18: =K18-H18 -> 10406.351 | M18: =L18/K18 -> 0.1288162 | O18: 82068.99
B19: SUBITEM | C19: Caixa de Instrumental | D19: QTD | E19: Valor Unit Bruto | F19: Valor Total Bruto | G19: Valor Unit sem ICMS | H19: Valor Total sem ICMS | I19: Aliquota % ICMS
B20: 1.1 | C20: CAIXA CIRURGIA CORONÁRIA | D20: 3 | E20: ='PROPOSTAS LISTA '!H53 -> 9194.8112 | F20: =E20*D20 -> 27584.434 | G20: ='PROPOSTAS LISTA '!J53 -> 9194.8112 | H20: =G20*D20 -> 27584.434 | I20: 0 | N20: 11187.74 | O20: 33563.21
B21: 1.2 | C21: CAIXA CIRURGIA DE VÁLVULA CARDÍACA | D21: 3 | E21: ='PROPOSTAS LISTA '!H110 -> 12816.322 | F21: =E21*D21 -> 38448.965 | G21: ='PROPOSTAS LISTA '!J110 -> 12816.322 | H21: =G21*D21 -> 38448.965 | I21: 0 | N21: 14128.6 | O21: 42385.81
B22: 1.3 | C22: CAIXA CIRURGIA CARDIOVASCULAR DELICADA | D22: 3 | E22: ='PROPOSTAS LISTA '!H129 -> 1448.2468 | F22: =E22*D22 -> 4344.7404 | G22: ='PROPOSTAS LISTA '!J129 -> 1448.2468 | H22: =G22*D22 -> 4344.7404 | I22: 0 | N22: 2039.99 | O22: 6119.97
B24: 2 | C24: Serviço de Locação de Instrumentais para Cirurgia de Laparotomia | H24: =SUM(H26:H27) -> 37892.478 | K24: 38653.83 | L24: =K24-H24 -> 761.35157 | M24: =L24/K24 -> 0.019696666 | O24: 37619.34
B25: SUBITEM | C25: Caixa de Instrumental | D25: QTD | E25: Valor Unit Bruto | F25: Valor Total Bruto | G25: Valor Unit sem ICMS | H25: Valor Total sem ICMS | I25: Aliquota % ICMS
B26: 2.1 | C26: CAIXA LAPAROTOMIA ADULTO | D26: 4 | E26: ='PROPOSTAS LISTA '!H186 -> 4644.007 | F26: =E26*D26 -> 18576.028 | G26: ='PROPOSTAS LISTA '!J186 -> 4644.007 | H26: =G26*D26 -> 18576.028 | I26: 0 | N26: 5484.52 | O26: 21938.09
B27: 2.2 | C27: CAIXA LAPAROTOMIA INFANTIL | D27: 4 | E27: ='PROPOSTAS LISTA '!H240 -> 4829.1126 | F27: =E27*D27 -> 19316.45 | G27: ='PROPOSTAS LISTA '!J240 -> 4829.1126 | H27: =G27*D27 -> 19316.45 | I27: 0 | N27: 3920.31 | O27: 15681.26
B29: 3 | C29: Serviço de Locação de Instrumentais para Cirurgia Geral | H29: =SUM(H31:H32) -> 13500.072 | K29: 11842.24 | L29: =K29-H29 -> -1657.8324 | M29: =L29/K29 -> -0.13999315 | O29: 11686.72
B30: SUBITEM | C30: Caixa de Instrumental | D30: QTD | E30: Valor Unit Bruto | F30: Valor Total Bruto | G30: Valor Unit sem ICMS | H30: Valor Total sem ICMS | I30: Aliquota % ICMS | N30: 2478.99 | O30: 7436.97
B31: 3.1 | C31: CAIXA CIRURGIA GERAL MEDIO PORTE | D31: 3 | E31: ='PROPOSTAS LISTA '!H281 -> 2857.9038 | F31: =E31*D31 -> 8573.7115 | G31: ='PROPOSTAS LISTA '!J281 -> 2857.9038 | H31: =G31*D31 -> 8573.7115 | I31: 0 | N31: 2124.88 | O31: 4249.75
B32: 3.2 | C32: CAIXA CIRURGIA GERAL PEQUENO PORTE | D32: 2 | E32: ='PROPOSTAS LISTA '!H315 -> 2463.1805 | F32: =E32*D32 -> 4926.3609 | G32: ='PROPOSTAS LISTA '!J315 -> 2463.1805 | H32: =G32*D32 -> 4926.3609 | I32: 0
B34: 4 | C34: Serviço de Locação de Instrumentais para Cirurgia de Otorrinolaringologia | H34: =SUM(H36:H37) -> 12003.822 | K34: 12066.44 | L34: =K34-H34 -> 62.61768 | M34: =L34/K34 -> 0.005189408 | O34: 12066.44
B35: SUBITEM | C35: Caixa de Instrumental | D35: QTD | E35: Valor Unit Bruto | F35: Valor Total Bruto | G35: Valor Unit sem ICMS | H35: Valor Total sem ICMS | I35: Aliquota % ICMS
B36: 4.1 | C36: CAIXA RINOPLASTIA | D36: 1 | E36: ='PROPOSTAS LISTA '!H340 -> 7749.3143 | F36: =E36*D36 -> 7749.3143 | G36: ='PROPOSTAS LISTA '!J340 -> 7749.3143 | H36: =G36*D36 -> 7749.3143 | I36: 0 | N36: 1734.89 | O36: 1734.89
B37: 4.2 | C37: CAIXA OTORRINO PARA PS | D37: 1 | E37: ='PROPOSTAS LISTA '!H368 -> 4254.508 | F37: =E37*D37 -> 4254.508 | G37: ='PROPOSTAS LISTA '!J368 -> 4254.508 | H37: =G37*D37 -> 4254.508 | I37: 0 | N37: 3850.78 | O37: 3850.78
B39: 5 | C39: Serviço de Locação de Instrumetais para Cirurgia Neurológicas | H39: =SUM(H41:H43) -> 67651.95 | K39: 67698.94 | L39: =K39-H39 -> 46.9896 | M39: =L39/K39 -> 0.00069409654 | O39: 65418.83
B40: SUBITEM | C40: Caixa de Instrumental | D40: QTD | E40: Valor Unit Bruto | F40: Valor Total Bruto | G40: Valor Unit sem ICMS | H40: Valor Total sem ICMS | I40: Aliquota % ICMS | N40: 12596.89 | O40: 25193.77
B41: 5.1 | C41: CAIXA DE LAMINECTOMIA | D41: 2 | E41: ='PROPOSTAS LISTA '!H439 -> 13780.246 | F41: =E41*D41 -> 27560.493 | G41: ='PROPOSTAS LISTA '!J439 -> 13780.246 | H41: =G41*D41 -> 27560.493 | I41: 0 | N41: 14194.66 | O41: 28389.32
B42: 5.2 | C42: CAIXA CIRURGIA CRANIOTOMIA | D42: 2 | E42: ='PROPOSTAS LISTA '!H533 -> 16874.234 | F42: =E42*D42 -> 33748.467 | G42: ='PROPOSTAS LISTA '!J533 -> 16874.234 | H42: =G42*D42 -> 33748.467 | I42: 0 | N42: 5917.87 | O42: 11835.74
B43: 5.3 | C43: CAIXA BASICA NEUROCIRURGIA | D43: 1 | E43: ='PROPOSTAS LISTA '!H590 -> 6342.9901 | F43: =E43*D43 -> 6342.9901 | G43: ='PROPOSTAS LISTA '!J590 -> 6342.9901 | H43: =G43*D43 -> 6342.9901 | I43: 0
B45: 6 | C45: Serviço de Locação de Instrumentais para Cirurgias Gastroenterológica | H45: =SUM(H47:H48) -> 21901.035 | K45: 19959.99 | L45: =K45-H45 -> -1941.045 | M45: =L45/K45 -> -0.097246793 | O45: 19199.97
B46: SUBITEM | C46: Caixa de Instrumental | D46: QTD | E46: Valor Unit Bruto | F46: Valor Total Bruto | G46: Valor Unit sem ICMS | H46: Valor Total sem ICMS | I46: Aliquota % ICMS
B47: 6.1 | C47: CAIXA DE COLECISTECTOMIA | D47: 3 | E47: ='PROPOSTAS LISTA '!H643 -> 4693.2319 | F47: =E47*D47 -> 14079.696 | G47: ='PROPOSTAS LISTA '!J643 -> 4693.2319 | H47: =G47*D47 -> 14079.696 | I47: 0 | N47: 4231.32 | O47: 12693.95
B48: 6.2 | C48: CAIXA APENDICECTOMIA E CISTOSTOMIA | D48: 3 | E48: ='PROPOSTAS LISTA '!H676 -> 2607.1131 | F48: =E48*D48 -> 7821.3394 | G48: ='PROPOSTAS LISTA '!J676 -> 2607.1131 | H48: =G48*D48 -> 7821.3394 | I48: 0 | N48: 2168.68 | O48: 6506.03
B50: 7 | C50: Serviço de Locação de Instrumentais para Cirurgias Torácica | H50: =SUM(H52:H53) -> 11930.908 | K50: 13301.7 | L50: =K50-H50 -> 1370.7921 | M50: =L50/K50 -> 0.1030539 | O50: 12916.11
B51: SUBITEM | C51: Caixa de Instrumental | D51: QTD | E51: Valor Unit Bruto | F51: Valor Total Bruto | G51: Valor Unit sem ICMS | H51: Valor Total sem ICMS | I51: Aliquota % ICMS
...

Sheet PROPOSTAS LISTA  
B2: SUBITEM 1.1 - Caixa para Cirurgia Coronária
A3: ITEM | B3: DESCRITIVO | C3: QTD | D3: CODIGO | E3: MARCA | F3: ANVISA | G3: Valor Unit Bruto | H3: Valor Total Bruto | I3: Valor Unit sem ICMS | J3: Valor Total sem ICMS | K3: Aliquota % ICMS
A4: 1 | B4: Acessório afastador mamária acoplado | C4: 2 | D4: QZ.015.00 | E4: Quinelato | F4: 10301950027 | G4: =M4 -> 623.99104 | H4: =G4*C4 -> 1247.9821 | I4: =G4 -> 623.99104 | J4: =I4*C4 -> 1247.9821 | K4: 0 | M4: 623.99104
A5: 2 | B5: Afastador Dinkhuysen mamária, tamanho adulto | C5: 1 | D5: QZ.013.01 | E5: Quinelato | F5: 10301950026 | G5: =M5 -> 270.32 | H5: =G5*C5 -> 270.32 | I5: =G5 -> 270.32 | J5: =I5*C5 -> 270.32 | K5: 0 | M5: =VLOOKUP(D5,'TABELA DE PRECOS'!B:C,2,0) -> 270.32
A6: 3 | B6: Finochietto Afastador de Costelas, 74x64mm, 245mm - inclui acessórios | C6: 2 | D6: FX.14.456 | E6: Fentex | F6: 81897719002 | G6: =M6 -> 473.3248 | H6: =G6*C6 -> 946.6496 | I6: =G6 -> 473.3248 | J6: =I6*C6 -> 946.6496 | K6: 0 | M6: =VLOOKUP(D6,'TABELA DE PRECOS'!B:C,2,0) -> 473.3248
A7: 4 | B7: Afastador Mollison, garras com 4 x 4 dentes , hastes comcurva acentuada, movimento por cremalheira, 15cm | C7: 2 | D7: FX.11.218 | E7: Fentex | F7: 81897719002 | G7: =M7 -> 121.71328 | H7: =G7*C7 -> 243.42656 | I7: =G7 -> 121.71328 | J7: =I7*C7 -> 243.42656 | K7: 0 | M7: =VLOOKUP(D7,'TABELA DE PRECOS'!B:C,2,0) -> 121.71328
A8: 5 | B8: Afastador Farabeuf, par com 2 válvulas duplas de lâmina plana, 15cm | C8: 2 | D8: FX.10.729 | E8: Fentex | F8: 81897719002 | G8: =M8 -> 17.19688 | H8: =G8*C8 -> 34.39376 | I8: =G8 -> 17.19688 | J8: =I8*C8 -> 34.39376 | K8: 0 | M8: =VLOOKUP(D8,'TABELA DE PRECOS'!B:C,2,0) -> 17.19688
A9: 6 | B9: Cabo de Bisturi, #3L, 20cm | C9: 2 | D9: FX.18.092 | E9: Fentex | F9: 81897719002 | G9: =M9 -> 12.17216 | H9: =G9*C9 -> 24.34432 | I9: =G9 -> 12.17216 | J9: =I9*C9 -> 24.34432 | K9: 0 | M9: =VLOOKUP(D9,'TABELA DE PRECOS'!B:C,2,0) -> 12.17216
A10: 7 | B10: Cabo de bisturi nº 4, standard, 12cm | C10: 2 | D10: FX.09.156 | E10: Fentex | F10: 81897719002 | G10: =M10 -> 8.25 | H10: =G10*C10 -> 16.5 | I10: =G10 -> 8.25 | J10: =I10*C10 -> 16.5 | K10: 0 | M10: =VLOOKUP(D10,'TABELA DE PRECOS'!B:C,2,0) -> 8.25
A11: 8 | B11: Cabo de Bisturi, #7, 16cm | C11: 2 | D11: FX.18.097 | E11: Fentex | F11: 81897719002 | G11: =M11 -> 8.112 | H11: =G11*C11 -> 16.224 | I11: =G11 -> 8.112 | J11: =I11*C11 -> 16.224 | K11: 0 | M11: =VLOOKUP(D11,'TABELA DE PRECOS'!B:C,2,0) -> 8.112
A12: 9 | B12: Cortador de fios de aço, lâminas anguladas com wídea TC e corte diagonal, 20cm | C12: 2 | D12: FX.12.420 | E12: Fentex | F12: 81897719003 | G12: =M12 -> 189.33824 | H12: =G12*C12 -> 378.67648 | I12: =G12 -> 189.33824 | J12: =I12*C12 -> 378.67648 | K12: 0 | M12: =VLOOKUP(D12,'TABELA DE PRECOS'!B:C,2,0) -> 189.33824
A13: 10 | B13: Diethrich Bulldog Clamp, serrilhado, angulada, mandibula de 12mm, 50mm | C13: 4 | D13: FX.10.247 | E13: Fentex | F13: 81897719002 | G13: =M13 -> 68.73808 | H13: =G13*C13 -> 274.95232 | I13: =G13 -> 68.73808 | J13: =I13*C13 -> 274.95232 | K13: 0 | M13: =VLOOKUP(D13,'TABELA DE PRECOS'!B:C,2,0) -> 68.73808
A14: 11 | B14: Simon Colher Uterina, afiada, rigida, 8.5mm, 20cm | C14: 2 | D14: FX.41.867 | E14: Fentex | F14: 81897719006 | G14: =M14 -> 29.73568 | H14: =G14*C14 -> 59.47136 | I14: =G14 -> 29.73568 | J14: =I14*C14 -> 59.47136 | K14: 0 | M14: =VLOOKUP(D14,'TABELA DE PRECOS'!B:C,2,0) -> 29.73568
A15: 12 | B15: Estilete para passar fios, ponta em gancho, calibre de 1.5mm, 26cm | C15: 2 | D15: FX.14.236 | E15: Fentex | F15: 81897719002 | G15: =M15 -> 18.94464 | H15: =G15*C15 -> 37.88928 | I15: =G15 -> 18.94464 | J15: =I15*C15 -> 37.88928 | K15: 0 | M15: =VLOOKUP(D15,'TABELA DE PRECOS'!B:C,2,0) -> 18.94464
A16: 13 | B16: Pinça Moynihan, pontas curvas e serrilhadas, 22cm | C16: 2 | D16: FX.41.925 | E16: Fentex | F16: 81897719006 | G16: =M16 -> 33.79584 | H16: =G16*C16 -> 67.59168 | I16: =G16 -> 33.79584 | J16: =I16*C16 -> 67.59168 | K16: 0 | M16: =VLOOKUP(D16,'TABELA DE PRECOS'!B:C,2,0) -> 33.79584
... A28: 25 | B28: DeBakey Pean Pinça Atraumatica Arterial, reta, 18cm | C28: 2 | D28: FX.14.000 | E28: Fentex | F28: 81897719002 | G28: =M28 -> 70.99456 | H28: =G28*C28 -> 141.98912 | I28: =G28 -> 70.99456 | J28: =I28*C28 -> 141.98912 | K28: 0 | M28: =VLOOKUP(D28,'TABELA DE PRECOS'!B:C,2,0) -> 70.99456
A29: 26 | B29: Pinça Clamp Vascular, 23cm | C29: 2 | D29: FX.14.037 | E29: Fentex | F29: 81897719002 | G29: 152.13952 | H29: 304.27904 | I29: 152.13952 | J29: 304.27904 | K29: 0 | M29: 152.13952
A30: 27 | B30: Pinça Debakey Rumel, curvo, 26cm | C30: 2 | D30: QZ.420.01 | E30: Quinelato | F30: 10301950027 | G30: =M30 -> 33.79584 | H30: =G30*C30 -> 67.59168 | I30: =G30 -> 33.79584 | J30: =I30*C30 -> 67.59168 | K30: 0 | M30: =VLOOKUP(D30,'TABELA DE PRECOS'!B:C,2,0) -> 33.79584
A31: 28 | B31: Clamp universal Cooley, parte funcional angulada em 15º com serrilha atraumática de 50mm, 17cm | C31: 2 | D31: FX.14.126 | E31: Fentex | F31: 81897719002 | G31: =M31 -> 169.05408 | H31: =G31*C31 -> 338.10816 | I31: =G31 -> 169.05408 | J31: =I31*C31 -> 338.10816 | K31: 0 | M31: =VLOOKUP(D31,'TABELA DE PRECOS'!B:C,2,0) -> 169.05408
A32: 29 | B32: Pinça Allis, pontas retas com 5 x 6 dentes, 25cm | C32: 4 | D32: FX.16.292 | E32: Fentex | F32: 81897719002 | G32: =M32 -> 29.99 | H32: =G32*C32 -> 119.96 | I32: =G32 -> 29.99 | J32: =I32*C32 -> 119.96 | K32: 0 | M32: =VLOOKUP(D32,'TABELA DE PRECOS'!B:C,2,0) -> 29.99
A33: 30 | B33: Pinça Cheron, pontas retas e serrilhadas, formato baioneta, 25cm | C33: 1 | D33: FX.10.688 | E33: Fentex | F33: 81897719002 | G33: =M33 -> 40.79 | H33: =G33*C33 -> 40.79 | I33: =G33 -> 40.79 | J33: =I33*C33 -> 40.79 | K33: 0 | M33: =VLOOKUP(D33,'TABELA DE PRECOS'!B:C,2,0) -> 40.79
A34: 31 | B34: Backhaus Clamp Toalha, 13cm | C34: 15 | D34: FX.18.425 | E34: Fentex | F34: 81897719002 | G34: =M34 -> 17.28 | H34: =G34*C34 -> 259.2 | I34: =G34 -> 17.28 | J34: =I34*C34 -> 259.2 | K34: 0 | M34: =VLOOKUP(D34,'TABELA DE PRECOS'!B:C,2,0) -> 17.28
A35: 32 | B35: Pinça Halsted-Mosquito, pontas curva, finas e serrilhadas, 12.5cm | C35: 15 | D35: FX.10.259 | E35: Fentex | F35: 81897719002 | G35: =M35 -> 15.95 | H35: =G35*C35 -> 239.25 | I35: =G35 -> 15.95 | J35: =I35*C35 -> 239.25 | K35: 0 | M35: =VLOOKUP(D35,'TABELA DE PRECOS'!B:C,2,0) -> 15.95
A36: 33 | B36: Pinça Kelly, pontas retas, finas e serrilhadas, 14cm | C36: 10 | D36: FX.10.281 | E36: Fentex | F36: 81897719002 | G36: =M36 -> 16.71 | H36: =G36*C36 -> 167.1 | I36: =G36 -> 16.71 | J36: =I36*C36 -> 167.1 | K36: 0 | M36: =VLOOKUP(D36,'TABELA DE PRECOS'!B:C,2,0) -> 16.71
A37: 34 | B37: Pinça Reynald para tubos, pontas retas e lisas, 20cm | C37: 1 | D37: FX.10.608 | E37: Fentex | F37: 81897719002 | G37: =M37 -> 25.68384 | H37: =G37*C37 -> 25.68384 | I37: =G37 -> 25.68384 | J37: =I37*C37 -> 25.68384 | K37: 0 | M37: =VLOOKUP(D37,'TABELA DE PRECOS'!B:C,2,0) -> 25.68384
A38: 35 | B38: Pinça Baby-Mixter, pontas curvas, muito finas e serrilhadas, 18cm | C38: 2 | D38: FX.10.432 | E38: Fentex | F38: 81897719002 | G38: =M38 -> 24.34432 | H38: =G38*C38 -> 48.68864 | I38: =G38 -> 24.34432 | J38: =I38*C38 -> 48.68864 | K38: 0 | M38: =VLOOKUP(D38,'TABELA DE PRECOS'!B:C,2,0) -> 24.34432
A39: 36 | B39: Pinça Anatômica Standard, pontas retas, largas e serrilhadas, 18cm | C39: 4 | D39: FX.09.951 | E39: Fentex | F39: 81897719002 | G39: =M39 -> 9.04 | H39: =G39*C39 -> 36.16 | I39: =G39 -> 9.04 | J39: =I39*C39 -> 36.16 | K39: 0 | M39: =VLOOKUP(D39,'TABELA DE PRECOS'!B:C,2,0) -> 9.04
A40: 37 | B40: Castroviejo Porta Agulha, reto, com trava, 17cm | C40: 1 | D40: FX.18.506 | E40: Fentex | F40: 81897719002 | G40: =M40 -> 94.64832 | H40: =G40*C40 -> 94.64832 | I40: =G40 -> 94.64832 | J40: =I40*C40 -> 94.64832 | K40: 0 | M40: =VLOOKUP(D40,'TABELA DE PRECOS'!B:C,2,0) -> 94.64832
A41: 38 | B41: Porta Agulha para Fio Mayo Hauberisser, 16cm, com videa - TC | C41: 2 | D41: FX.12.399 | E41: Fentex | F41: 81897719003 | G41: =M41 -> 94.64832 | H41: =G41*C41 -> 189.29664 | I41: =G41 -> 94.64832 | J41: =I41*C41 -> 189.29664 | K41: 0 | M41: =VLOOKUP(D41,'TABELA DE PRECOS'!B:C,2,0) -> 94.64832
... A51: 48 | B51: Tesoura Mayo, lâminas retas, largas com pontas rombas, 14.5cm | C51: 4 | D51: FX.09.375 | E51: Fentex | F51: 81897719002 | G51: =M51 -> 17.36384 | H51: =G51*C51 -> 69.45536 | I51: =G51 -> 17.36384 | J51: =I51*C51 -> 69.45536 | K51: 0 | M51: =VLOOKUP(D51,'TABELA DE PRECOS'!B:C,2,0) -> 17.36384
A52: 49 | B52: Caixa inox perfurada com trava 500x200x120 mm | C52: 1 | D52: FX.41.521 | E52: Fentex | F52: Isento | G52: =M52 -> 590.62848 | H52: =G52*C52 -> 590.62848 | I52: =G52 -> 590.62848 | J52: =I52*C52 -> 590.62848 | K52: 0 | M52: =VLOOKUP(D52,'TABELA DE PRECOS'!B:C,2,0) -> 590.62848
B53: Total | C53: =SUM(C4:C52) -> 135 | H53: =SUM(H4:H52) -> 9194.8112 | J53: =SUM(J4:J52) -> 9194.8112 | M53: =VLOOKUP(D53,'TABELA DE PRECOS'!B:C,2,0) -> #N/A
M54: =VLOOKUP(D54,'TABELA DE PRECOS'!B:C,2,0) -> #N/A
B55: Subitem 1.2 - Caixa para Cirurgia de Válvula Cardíaca | M55: =VLOOKUP(D55,'TABELA DE PRECOS'!B:C,2,0) -> #N/A
A56: ITEM | B56: DESCRITIVO | C56: QTD | D56: CODIGO | E56: MARCA | F56: ANVISA | G56: Valor Unit Bruto | H56: Valor Total Bruto | I56: Valor Unit sem ICMS | J56: Valor Total sem ICMS | K56: Aliquota % ICMS | M56: =VLOOKUP(D56,'TABELA DE PRECOS'!B:C,2,0) -> Valor Unit Bruto
A57: 1 | B57: Afastador Mollison, garras com 4 x 4 dentes, hastes comcurva acentuada, movimento por cremalheira, 15cm | C57: 2 | D57: FX.11.218 | E57: Fentex | F57: 81897719002 | G57: =M57 -> 121.71328 | H57: =G57*C57 -> 243.42656 | I57: =G57 -> 121.71328 | J57: =I57*C57 -> 243.42656 | K57: 0 | M57: =VLOOKUP(D57,'TABELA DE PRECOS'!B:C,2,0) -> 121.71328
A58: 2 | B58: Afastador Ventrículo, tamanho pequeno, 20cm | C58: 2 | D58: QZ.044.01 | E58: Quinelato | F58: 10301950027 | G58: =M58 -> 209.85536 | H58: =G58*C58 -> 419.71072 | I58: =G58 -> 209.85536 | J58: =I58*C58 -> 419.71072 | K58: 0 | M58: =VLOOKUP(D58,'TABELA DE PRECOS'!B:C,2,0) -> 209.85536
A59: 3 | B59: Afastador Ventrículo, tamanho médio, 20cm | C59: 2 | D59: QZ.044.02 | E59: Quinelato | F59: 10301950027 | G59: =M59 -> 209.85536 | H59: =G59*C59 -> 419.71072 | I59: =G59 -> 209.85536 | J59: =I59*C59 -> 419.71072 | K59: 0 | M59: =VLOOKUP(D59,'TABELA DE PRECOS'!B:C,2,0) -> 209.85536
A60: 4 | B60: Afastador Cooley, válvula aramada lisa, fenestrada, curva p/esquerda, com dimensões de 45mm x 48mm, 21.5cm | C60: 1 | D60: FX.11.109 | E60: Fentex | F60: 81897719002 | G60: =M60 -> 135.21664 | H60: =G60*C60 -> 135.21664 | I60: =G60 -> 135.21664 | J60: =I60*C60 -> 135.21664 | K60: 0 | M60: =VLOOKUP(D60,'TABELA DE PRECOS'!B:C,2,0) -> 135.21664
A61: 5 | B61: Afastador Cooley, válvula aramada lisa, fenestrada, curva p/ direita, com dimensões de 45mm x 48mm, 21.5cm | C61: 1 | D61: FX.11.107 | E61: Fentex | F61: 81897719002 | G61: =M61 -> 135.21664 | H61: =G61*C61 -> 135.21664 | I61: =G61 -> 135.21664 | J61: =I61*C61 -> 135.21664 | K61: 0 | M61: =VLOOKUP(D61,'TABELA DE PRECOS'!B:C,2,0) -> 135.21664
...

Sheet TABELA DE PRECOS
A1: DESCRITIVO | B1: CODIGO | C1: Valor Unit Bruto
A2: Abridor de boca Molt Doyen Jansen, 11cm | B2: FX.15.555 | C2: 92.99664
A3: Acessório afastador mamária acoplado | B3: QZ.015.00 | C3: 353.99104
A4: Adson Alavanca Periosteal, 17cm, Fig.2 | B4: FX.13.193 | C4: 21.34896
A5: Adson Pinça Curativos, serrilhada, 19cm | B5: FX.18.333 | C5: 17.64672
A6: Afastador Adson, garras com dupla articulação e 3 x 4 dentes rombos, movimento por cremalheira, 16cm | B6: FX.11.246 | C6: 226.78128
A7: Afastador Adson, garras com dupla articulação e 3 x 4 dentes rombos, movimento por cremalheira, 26cm | B7: FX.11.248 | C7: 643.28
A8: Afastador Ankeney médio com quatro válvulas, lâminas de 3,5 mm à 4,0mm, com abertura entre 134 à 150 mm | B8: QZ.010.03 | C8: 463.49176
A9: Afastador Balfour, garras laterais aramadas com 100mm x 35mm, hastes curvas, abertura de 200mm, Acompanha válvula central plana com 100mm x 60mm | B9: FX.11.467 | C9: 205.0936
A10: Afastador Balfour, garras laterais aramadas com 70mm x 35mm, hastes curvas, abertura de 180mm, Acompanha válvula central suprapúbica com 45mm x 80mm | B10: FX.11.469 | C10: 216
A11: Afastador Balfour-Baby, garras laterais aramadas com 30mm x 27mm, hastes retas, abertura de 90mm, Acompanha válvula central suprapúbica com 20mm x 24mm | B11: FX.11.465 | C11: 177.984
A12: Afastador Beckmann-Eaton, garras com dupla articulação e 7 x 7 dentes agudos, movimento por cremalheira, 32cm | B12: FX.11.252 | C12: 266.71232
A13: Afastador Buenings, 19cm | B13: FX.15.636 | C13: 6.76504
... A49: Afastador Mollison, garras com 4 x 4 dentes agudos, hastes comcurva acentuada, movimento por cremalheira, 15cm | B49: FX.11.218 | C49: 121.71328
A50: Afastador Richardson 25cm – 24x20mm | B50: 10447 | C50: 23.29552
A51: Afastador Richardson 25cm – 33x29mm | B51: 10448 | C51: 23.29552
A52: Afastador Richardson 25cm – 50x22mm | B52: 10450 | C52: 36.54144
A53: Afastador Richardson 25cm 40×38 | B53: 10449 | C53: 23.29552
A54: Afastador Senn Miller, 3 garras rombas, 18cm | B54: FX.41.871 | C54: 10.68712
A55: Afastador Senn-Miller, duplo, de um lado, lâmina de 20mm x 7mm, e do outro, gancho com 3 dentes rombos, 16cm | B55: FX.10.858 | C55: 12.40944
A56: Afastador Ventrículo, tamanho médio, 20cm | B56: QZ.044.02 | C56: 209.85536
A57: Afastador Ventrículo, tamanho pequeno, 20cm | B57: QZ.044.01 | C57: 209.85536
A58: Afastador Volkmann, multi-uso, gancho com 2 dentes rombos, 22cm | B58: FX.10.901 | C58: 19.88904
A59: Afastador Volkmann, multi-uso, gancho com 2 dentes semi-rombos, 22cm | B59: FX.10.896 | C59: 19.88904
A60: Afastador Volkmann, multi-uso, gancho com 3 dentes rombos, 22cm | B60: FX.10.902 | C60: 18.48232
A61: Afastador Volkmann, multi-uso, gancho com 4 dentes rombos, 22cm | B61: FX.10.903 | C61: 19.33928
A62: Afastador Weitlaner, garras com3 x 4 dentes agudos, movimento por cremalheira,16cm | B62: FX.11.190 | C62: 87.36768
A63: Afastador Weitlaner, garras com 3 x 4 dentes rombos, movimento por cremalheira, 20cm | B63: FX.11.201 | C63: 144.46368
A64: Afastador Weitlaner, garras com 3 x 4 dentes rombos, movimento por cremalheira,14cm | B64: FX.11.192 | C64: 123.69888
A65: Afastador Weitlaner, garras com 3 x 4 dentes rombos, movimento por cremalheira,16cm | B65: FX.11.193 | C65: 133.35616
... A79: Alicate Ruskin Rugina Óssea, curva, 23cm | B79: FX.13.419 | C79: 244.4808
A80: ALICATE STEIMANN 30CM P/ FIO DE AÇO DUPLA ARTICULAÇÃO C/ VIDEA | B80: 11227 | C80: 675.82008
A81: ALICATE STEIMANN 60CM P/ FIO DE AÇO DUPLA ARTICULAÇÃO C/ VIDEA | B81: 13039 | C81: 918.01016
A82: Alicate Torce Fio Mayo Hauberisser, 16cm, com videa - TC | B82: FX.12.399 | C82: 94.64832
A83: Aplicador de Pinça para vaso Biemer, sem trava, 14.5cm | B83: HB3929-33 | C83: 230.62944
A84: Areolotomo, conjunto com 3 peças | B84: 51-274-34 | C84: 67.82344
A85: Aspirador Cautério | B85: FX.41.912 | C85: 162.87184
A86: Babcock Pinça para Tecido, serrilhada, 16cm | B86: FX.16.319 | C86: 24.102848
A87: Babcock Pinça para Tecido, serrilhada, 18cm | B87: FX.16.320 | C87: 27.50512
A88: Babcock Pinça para Tecido, serrilhada, 20cm | B88: FX.16.321 | C88: 32.45
...
